INFO:     Will watch for changes in these directories: ['/Users/quick/Desktop/bill_generator-main/backend']
INFO:     Uvicorn running on http://127.0.0.1:8000 (Press CTRL+C to quit)
INFO:     Started reloader process [82034] using StatReload
INFO:     Started server process [82091]
INFO:     Waiting for application startup.
2025-08-14 08:06:06,050 - server - INFO - ðŸš€ InvoiceForge API started successfully!
INFO:     Application startup complete.
INFO:     127.0.0.1:62716 - "GET /api/ HTTP/1.1" 200 OK
INFO:     127.0.0.1:62745 - "GET /api/ HTTP/1.1" 200 OK
INFO:     127.0.0.1:62747 - "OPTIONS /api/ HTTP/1.1" 200 OK
INFO:     127.0.0.1:62745 - "GET /api/ HTTP/1.1" 200 OK
INFO:     127.0.0.1:62791 - "OPTIONS /api/customers HTTP/1.1" 200 OK
INFO:     127.0.0.1:62792 - "OPTIONS /api/customers HTTP/1.1" 200 OK
INFO:     127.0.0.1:62791 - "GET /api/customers HTTP/1.1" 200 OK
INFO:     127.0.0.1:62791 - "GET /api/customers HTTP/1.1" 200 OK
INFO:     127.0.0.1:62794 - "OPTIONS /api/business/profile HTTP/1.1" 200 OK
INFO:     127.0.0.1:62811 - "OPTIONS /api/business/profile HTTP/1.1" 200 OK
INFO:     127.0.0.1:62794 - "GET /api/business/profile HTTP/1.1" 404 Not Found
INFO:     127.0.0.1:62794 - "GET /api/business/profile HTTP/1.1" 404 Not Found
INFO:     127.0.0.1:62813 - "OPTIONS /api/ai/enhanced-voice-processing HTTP/1.1" 200 OK
INFO:     127.0.0.1:62813 - "POST /api/ai/enhanced-voice-processing HTTP/1.1" 200 OK
INFO:     127.0.0.1:62827 - "OPTIONS /api/business/profile HTTP/1.1" 200 OK
INFO:     127.0.0.1:62827 - "POST /api/business/profile HTTP/1.1" 200 OK
INFO:     127.0.0.1:62827 - "OPTIONS /api/business/generate-template HTTP/1.1" 200 OK
INFO:     127.0.0.1:62835 - "POST /api/business/generate-template HTTP/1.1" 500 Internal Server Error
ERROR:    Exception in ASGI application
Traceback (most recent call last):
  File "/Users/quick/Desktop/bill_generator-main/backend/venv/lib/python3.13/site-packages/fastapi/encoders.py", line 322, in jsonable_encoder
    data = dict(obj)
TypeError: 'ObjectId' object is not iterable

During handling of the above exception, another exception occurred:

Traceback (most recent call last):
  File "/Users/quick/Desktop/bill_generator-main/backend/venv/lib/python3.13/site-packages/fastapi/encoders.py", line 327, in jsonable_encoder
    data = vars(obj)
TypeError: vars() argument must have __dict__ attribute

The above exception was the direct cause of the following exception:

Traceback (most recent call last):
  File "/Users/quick/Desktop/bill_generator-main/backend/venv/lib/python3.13/site-packages/uvicorn/protocols/http/h11_impl.py", line 408, in run_asgi
    result = await app(  # type: ignore[func-returns-value]
             ^^^^^^^^^^^^^^^^^^^^^^^^^^^^^^^^^^^^^^^^^^^^^^
        self.scope, self.receive, self.send
        ^^^^^^^^^^^^^^^^^^^^^^^^^^^^^^^^^^^
    )
    ^
  File "/Users/quick/Desktop/bill_generator-main/backend/venv/lib/python3.13/site-packages/uvicorn/middleware/proxy_headers.py", line 84, in __call__
    return await self.app(scope, receive, send)
           ^^^^^^^^^^^^^^^^^^^^^^^^^^^^^^^^^^^^
  File "/Users/quick/Desktop/bill_generator-main/backend/venv/lib/python3.13/site-packages/fastapi/applications.py", line 1054, in __call__
    await super().__call__(scope, receive, send)
  File "/Users/quick/Desktop/bill_generator-main/backend/venv/lib/python3.13/site-packages/starlette/applications.py", line 123, in __call__
    await self.middleware_stack(scope, receive, send)
  File "/Users/quick/Desktop/bill_generator-main/backend/venv/lib/python3.13/site-packages/starlette/middleware/errors.py", line 186, in __call__
    raise exc
  File "/Users/quick/Desktop/bill_generator-main/backend/venv/lib/python3.13/site-packages/starlette/middleware/errors.py", line 164, in __call__
    await self.app(scope, receive, _send)
  File "/Users/quick/Desktop/bill_generator-main/backend/venv/lib/python3.13/site-packages/starlette/middleware/cors.py", line 93, in __call__
    await self.simple_response(scope, receive, send, request_headers=headers)
  File "/Users/quick/Desktop/bill_generator-main/backend/venv/lib/python3.13/site-packages/starlette/middleware/cors.py", line 148, in simple_response
    await self.app(scope, receive, send)
  File "/Users/quick/Desktop/bill_generator-main/backend/venv/lib/python3.13/site-packages/starlette/middleware/exceptions.py", line 65, in __call__
    await wrap_app_handling_exceptions(self.app, conn)(scope, receive, send)
  File "/Users/quick/Desktop/bill_generator-main/backend/venv/lib/python3.13/site-packages/starlette/_exception_handler.py", line 64, in wrapped_app
    raise exc
  File "/Users/quick/Desktop/bill_generator-main/backend/venv/lib/python3.13/site-packages/starlette/_exception_handler.py", line 53, in wrapped_app
    await app(scope, receive, sender)
  File "/Users/quick/Desktop/bill_generator-main/backend/venv/lib/python3.13/site-packages/starlette/routing.py", line 756, in __call__
    await self.middleware_stack(scope, receive, send)
  File "/Users/quick/Desktop/bill_generator-main/backend/venv/lib/python3.13/site-packages/starlette/routing.py", line 776, in app
    await route.handle(scope, receive, send)
  File "/Users/quick/Desktop/bill_generator-main/backend/venv/lib/python3.13/site-packages/starlette/routing.py", line 297, in handle
    await self.app(scope, receive, send)
  File "/Users/quick/Desktop/bill_generator-main/backend/venv/lib/python3.13/site-packages/starlette/routing.py", line 77, in app
    await wrap_app_handling_exceptions(app, request)(scope, receive, send)
  File "/Users/quick/Desktop/bill_generator-main/backend/venv/lib/python3.13/site-packages/starlette/_exception_handler.py", line 64, in wrapped_app
    raise exc
  File "/Users/quick/Desktop/bill_generator-main/backend/venv/lib/python3.13/site-packages/starlette/_exception_handler.py", line 53, in wrapped_app
    await app(scope, receive, sender)
  File "/Users/quick/Desktop/bill_generator-main/backend/venv/lib/python3.13/site-packages/starlette/routing.py", line 72, in app
    response = await func(request)
               ^^^^^^^^^^^^^^^^^^^
  File "/Users/quick/Desktop/bill_generator-main/backend/venv/lib/python3.13/site-packages/fastapi/routing.py", line 296, in app
    content = await serialize_response(
              ^^^^^^^^^^^^^^^^^^^^^^^^^
    ...<9 lines>...
    )
    ^
  File "/Users/quick/Desktop/bill_generator-main/backend/venv/lib/python3.13/site-packages/fastapi/routing.py", line 180, in serialize_response
    return jsonable_encoder(response_content)
  File "/Users/quick/Desktop/bill_generator-main/backend/venv/lib/python3.13/site-packages/fastapi/encoders.py", line 287, in jsonable_encoder
    encoded_value = jsonable_encoder(
        value,
    ...<4 lines>...
        sqlalchemy_safe=sqlalchemy_safe,
    )
  File "/Users/quick/Desktop/bill_generator-main/backend/venv/lib/python3.13/site-packages/fastapi/encoders.py", line 287, in jsonable_encoder
    encoded_value = jsonable_encoder(
        value,
    ...<4 lines>...
        sqlalchemy_safe=sqlalchemy_safe,
    )
  File "/Users/quick/Desktop/bill_generator-main/backend/venv/lib/python3.13/site-packages/fastapi/encoders.py", line 330, in jsonable_encoder
    raise ValueError(errors) from e
ValueError: [TypeError("'ObjectId' object is not iterable"), TypeError('vars() argument must have __dict__ attribute')]
INFO:     127.0.0.1:62848 - "POST /api/business/profile HTTP/1.1" 200 OK
INFO:     127.0.0.1:62848 - "POST /api/business/profile HTTP/1.1" 200 OK
INFO:     127.0.0.1:62848 - "POST /api/business/generate-template HTTP/1.1" 500 Internal Server Error
ERROR:    Exception in ASGI application
Traceback (most recent call last):
  File "/Users/quick/Desktop/bill_generator-main/backend/venv/lib/python3.13/site-packages/fastapi/encoders.py", line 322, in jsonable_encoder
    data = dict(obj)
TypeError: 'ObjectId' object is not iterable

During handling of the above exception, another exception occurred:

Traceback (most recent call last):
  File "/Users/quick/Desktop/bill_generator-main/backend/venv/lib/python3.13/site-packages/fastapi/encoders.py", line 327, in jsonable_encoder
    data = vars(obj)
TypeError: vars() argument must have __dict__ attribute

The above exception was the direct cause of the following exception:

Traceback (most recent call last):
  File "/Users/quick/Desktop/bill_generator-main/backend/venv/lib/python3.13/site-packages/uvicorn/protocols/http/h11_impl.py", line 408, in run_asgi
    result = await app(  # type: ignore[func-returns-value]
             ^^^^^^^^^^^^^^^^^^^^^^^^^^^^^^^^^^^^^^^^^^^^^^
        self.scope, self.receive, self.send
        ^^^^^^^^^^^^^^^^^^^^^^^^^^^^^^^^^^^
    )
    ^
  File "/Users/quick/Desktop/bill_generator-main/backend/venv/lib/python3.13/site-packages/uvicorn/middleware/proxy_headers.py", line 84, in __call__
    return await self.app(scope, receive, send)
           ^^^^^^^^^^^^^^^^^^^^^^^^^^^^^^^^^^^^
  File "/Users/quick/Desktop/bill_generator-main/backend/venv/lib/python3.13/site-packages/fastapi/applications.py", line 1054, in __call__
    await super().__call__(scope, receive, send)
  File "/Users/quick/Desktop/bill_generator-main/backend/venv/lib/python3.13/site-packages/starlette/applications.py", line 123, in __call__
    await self.middleware_stack(scope, receive, send)
  File "/Users/quick/Desktop/bill_generator-main/backend/venv/lib/python3.13/site-packages/starlette/middleware/errors.py", line 186, in __call__
    raise exc
  File "/Users/quick/Desktop/bill_generator-main/backend/venv/lib/python3.13/site-packages/starlette/middleware/errors.py", line 164, in __call__
    await self.app(scope, receive, _send)
  File "/Users/quick/Desktop/bill_generator-main/backend/venv/lib/python3.13/site-packages/starlette/middleware/cors.py", line 93, in __call__
    await self.simple_response(scope, receive, send, request_headers=headers)
  File "/Users/quick/Desktop/bill_generator-main/backend/venv/lib/python3.13/site-packages/starlette/middleware/cors.py", line 148, in simple_response
    await self.app(scope, receive, send)
  File "/Users/quick/Desktop/bill_generator-main/backend/venv/lib/python3.13/site-packages/starlette/middleware/exceptions.py", line 65, in __call__
    await wrap_app_handling_exceptions(self.app, conn)(scope, receive, send)
  File "/Users/quick/Desktop/bill_generator-main/backend/venv/lib/python3.13/site-packages/starlette/_exception_handler.py", line 64, in wrapped_app
    raise exc
  File "/Users/quick/Desktop/bill_generator-main/backend/venv/lib/python3.13/site-packages/starlette/_exception_handler.py", line 53, in wrapped_app
    await app(scope, receive, sender)
  File "/Users/quick/Desktop/bill_generator-main/backend/venv/lib/python3.13/site-packages/starlette/routing.py", line 756, in __call__
    await self.middleware_stack(scope, receive, send)
  File "/Users/quick/Desktop/bill_generator-main/backend/venv/lib/python3.13/site-packages/starlette/routing.py", line 776, in app
    await route.handle(scope, receive, send)
  File "/Users/quick/Desktop/bill_generator-main/backend/venv/lib/python3.13/site-packages/starlette/routing.py", line 297, in handle
    await self.app(scope, receive, send)
  File "/Users/quick/Desktop/bill_generator-main/backend/venv/lib/python3.13/site-packages/starlette/routing.py", line 77, in app
    await wrap_app_handling_exceptions(app, request)(scope, receive, send)
  File "/Users/quick/Desktop/bill_generator-main/backend/venv/lib/python3.13/site-packages/starlette/_exception_handler.py", line 64, in wrapped_app
    raise exc
  File "/Users/quick/Desktop/bill_generator-main/backend/venv/lib/python3.13/site-packages/starlette/_exception_handler.py", line 53, in wrapped_app
    await app(scope, receive, sender)
  File "/Users/quick/Desktop/bill_generator-main/backend/venv/lib/python3.13/site-packages/starlette/routing.py", line 72, in app
    response = await func(request)
               ^^^^^^^^^^^^^^^^^^^
  File "/Users/quick/Desktop/bill_generator-main/backend/venv/lib/python3.13/site-packages/fastapi/routing.py", line 296, in app
    content = await serialize_response(
              ^^^^^^^^^^^^^^^^^^^^^^^^^
    ...<9 lines>...
    )
    ^
  File "/Users/quick/Desktop/bill_generator-main/backend/venv/lib/python3.13/site-packages/fastapi/routing.py", line 180, in serialize_response
    return jsonable_encoder(response_content)
  File "/Users/quick/Desktop/bill_generator-main/backend/venv/lib/python3.13/site-packages/fastapi/encoders.py", line 287, in jsonable_encoder
    encoded_value = jsonable_encoder(
        value,
    ...<4 lines>...
        sqlalchemy_safe=sqlalchemy_safe,
    )
  File "/Users/quick/Desktop/bill_generator-main/backend/venv/lib/python3.13/site-packages/fastapi/encoders.py", line 287, in jsonable_encoder
    encoded_value = jsonable_encoder(
        value,
    ...<4 lines>...
        sqlalchemy_safe=sqlalchemy_safe,
    )
  File "/Users/quick/Desktop/bill_generator-main/backend/venv/lib/python3.13/site-packages/fastapi/encoders.py", line 330, in jsonable_encoder
    raise ValueError(errors) from e
ValueError: [TypeError("'ObjectId' object is not iterable"), TypeError('vars() argument must have __dict__ attribute')]
INFO:     127.0.0.1:62852 - "POST /api/business/profile HTTP/1.1" 200 OK
INFO:     127.0.0.1:62852 - "POST /api/business/generate-template HTTP/1.1" 500 Internal Server Error
ERROR:    Exception in ASGI application
Traceback (most recent call last):
  File "/Users/quick/Desktop/bill_generator-main/backend/venv/lib/python3.13/site-packages/fastapi/encoders.py", line 322, in jsonable_encoder
    data = dict(obj)
TypeError: 'ObjectId' object is not iterable

During handling of the above exception, another exception occurred:

Traceback (most recent call last):
  File "/Users/quick/Desktop/bill_generator-main/backend/venv/lib/python3.13/site-packages/fastapi/encoders.py", line 327, in jsonable_encoder
    data = vars(obj)
TypeError: vars() argument must have __dict__ attribute

The above exception was the direct cause of the following exception:

Traceback (most recent call last):
  File "/Users/quick/Desktop/bill_generator-main/backend/venv/lib/python3.13/site-packages/uvicorn/protocols/http/h11_impl.py", line 408, in run_asgi
    result = await app(  # type: ignore[func-returns-value]
             ^^^^^^^^^^^^^^^^^^^^^^^^^^^^^^^^^^^^^^^^^^^^^^
        self.scope, self.receive, self.send
        ^^^^^^^^^^^^^^^^^^^^^^^^^^^^^^^^^^^
    )
    ^
  File "/Users/quick/Desktop/bill_generator-main/backend/venv/lib/python3.13/site-packages/uvicorn/middleware/proxy_headers.py", line 84, in __call__
    return await self.app(scope, receive, send)
           ^^^^^^^^^^^^^^^^^^^^^^^^^^^^^^^^^^^^
  File "/Users/quick/Desktop/bill_generator-main/backend/venv/lib/python3.13/site-packages/fastapi/applications.py", line 1054, in __call__
    await super().__call__(scope, receive, send)
  File "/Users/quick/Desktop/bill_generator-main/backend/venv/lib/python3.13/site-packages/starlette/applications.py", line 123, in __call__
    await self.middleware_stack(scope, receive, send)
  File "/Users/quick/Desktop/bill_generator-main/backend/venv/lib/python3.13/site-packages/starlette/middleware/errors.py", line 186, in __call__
    raise exc
  File "/Users/quick/Desktop/bill_generator-main/backend/venv/lib/python3.13/site-packages/starlette/middleware/errors.py", line 164, in __call__
    await self.app(scope, receive, _send)
  File "/Users/quick/Desktop/bill_generator-main/backend/venv/lib/python3.13/site-packages/starlette/middleware/cors.py", line 93, in __call__
    await self.simple_response(scope, receive, send, request_headers=headers)
  File "/Users/quick/Desktop/bill_generator-main/backend/venv/lib/python3.13/site-packages/starlette/middleware/cors.py", line 148, in simple_response
    await self.app(scope, receive, send)
  File "/Users/quick/Desktop/bill_generator-main/backend/venv/lib/python3.13/site-packages/starlette/middleware/exceptions.py", line 65, in __call__
    await wrap_app_handling_exceptions(self.app, conn)(scope, receive, send)
  File "/Users/quick/Desktop/bill_generator-main/backend/venv/lib/python3.13/site-packages/starlette/_exception_handler.py", line 64, in wrapped_app
    raise exc
  File "/Users/quick/Desktop/bill_generator-main/backend/venv/lib/python3.13/site-packages/starlette/_exception_handler.py", line 53, in wrapped_app
    await app(scope, receive, sender)
  File "/Users/quick/Desktop/bill_generator-main/backend/venv/lib/python3.13/site-packages/starlette/routing.py", line 756, in __call__
    await self.middleware_stack(scope, receive, send)
  File "/Users/quick/Desktop/bill_generator-main/backend/venv/lib/python3.13/site-packages/starlette/routing.py", line 776, in app
    await route.handle(scope, receive, send)
  File "/Users/quick/Desktop/bill_generator-main/backend/venv/lib/python3.13/site-packages/starlette/routing.py", line 297, in handle
    await self.app(scope, receive, send)
  File "/Users/quick/Desktop/bill_generator-main/backend/venv/lib/python3.13/site-packages/starlette/routing.py", line 77, in app
    await wrap_app_handling_exceptions(app, request)(scope, receive, send)
  File "/Users/quick/Desktop/bill_generator-main/backend/venv/lib/python3.13/site-packages/starlette/_exception_handler.py", line 64, in wrapped_app
    raise exc
  File "/Users/quick/Desktop/bill_generator-main/backend/venv/lib/python3.13/site-packages/starlette/_exception_handler.py", line 53, in wrapped_app
    await app(scope, receive, sender)
  File "/Users/quick/Desktop/bill_generator-main/backend/venv/lib/python3.13/site-packages/starlette/routing.py", line 72, in app
    response = await func(request)
               ^^^^^^^^^^^^^^^^^^^
  File "/Users/quick/Desktop/bill_generator-main/backend/venv/lib/python3.13/site-packages/fastapi/routing.py", line 296, in app
    content = await serialize_response(
              ^^^^^^^^^^^^^^^^^^^^^^^^^
    ...<9 lines>...
    )
    ^
  File "/Users/quick/Desktop/bill_generator-main/backend/venv/lib/python3.13/site-packages/fastapi/routing.py", line 180, in serialize_response
    return jsonable_encoder(response_content)
  File "/Users/quick/Desktop/bill_generator-main/backend/venv/lib/python3.13/site-packages/fastapi/encoders.py", line 287, in jsonable_encoder
    encoded_value = jsonable_encoder(
        value,
    ...<4 lines>...
        sqlalchemy_safe=sqlalchemy_safe,
    )
  File "/Users/quick/Desktop/bill_generator-main/backend/venv/lib/python3.13/site-packages/fastapi/encoders.py", line 287, in jsonable_encoder
    encoded_value = jsonable_encoder(
        value,
    ...<4 lines>...
        sqlalchemy_safe=sqlalchemy_safe,
    )
  File "/Users/quick/Desktop/bill_generator-main/backend/venv/lib/python3.13/site-packages/fastapi/encoders.py", line 330, in jsonable_encoder
    raise ValueError(errors) from e
ValueError: [TypeError("'ObjectId' object is not iterable"), TypeError('vars() argument must have __dict__ attribute')]
INFO:     127.0.0.1:62862 - "GET /api/customers HTTP/1.1" 200 OK
INFO:     127.0.0.1:62862 - "GET /api/customers HTTP/1.1" 200 OK
INFO:     127.0.0.1:62877 - "OPTIONS /api/invoices HTTP/1.1" 200 OK
INFO:     127.0.0.1:62878 - "OPTIONS /api/invoices HTTP/1.1" 200 OK
INFO:     127.0.0.1:62877 - "GET /api/invoices HTTP/1.1" 200 OK
INFO:     127.0.0.1:62877 - "GET /api/invoices HTTP/1.1" 200 OK
INFO:     127.0.0.1:62880 - "GET /api/ HTTP/1.1" 200 OK
INFO:     127.0.0.1:62880 - "GET /api/ HTTP/1.1" 200 OK
INFO:     127.0.0.1:62904 - "GET /api/dashboard/stats HTTP/1.1" 200 OK
INFO:     127.0.0.1:62942 - "GET /api/customers HTTP/1.1" 200 OK
INFO:     127.0.0.1:62942 - "GET /api/customers HTTP/1.1" 200 OK
INFO:     127.0.0.1:62942 - "GET /api/business/profile HTTP/1.1" 404 Not Found
INFO:     127.0.0.1:62942 - "GET /api/business/profile HTTP/1.1" 404 Not Found
INFO:     127.0.0.1:62942 - "GET /api/customers HTTP/1.1" 200 OK
INFO:     127.0.0.1:62942 - "GET /api/customers HTTP/1.1" 200 OK
INFO:     127.0.0.1:62942 - "GET /api/ HTTP/1.1" 200 OK
INFO:     127.0.0.1:62942 - "GET /api/ HTTP/1.1" 200 OK
INFO:     127.0.0.1:62980 - "GET / HTTP/1.1" 404 Not Found
INFO:     127.0.0.1:62980 - "GET /favicon.ico HTTP/1.1" 404 Not Found
INFO:     127.0.0.1:62980 - "GET / HTTP/1.1" 404 Not Found
INFO:     127.0.0.1:62980 - "GET / HTTP/1.1" 404 Not Found
INFO:     127.0.0.1:62980 - "GET / HTTP/1.1" 404 Not Found
INFO:     127.0.0.1:63127 - "GET /health HTTP/1.1" 404 Not Found
INFO:     127.0.0.1:63163 - "GET /api/ HTTP/1.1" 200 OK
INFO:     127.0.0.1:63165 - "OPTIONS /api/ HTTP/1.1" 200 OK
INFO:     127.0.0.1:63163 - "GET /api/ HTTP/1.1" 200 OK
INFO:     127.0.0.1:63176 - "OPTIONS /api/customers HTTP/1.1" 200 OK
INFO:     127.0.0.1:63177 - "OPTIONS /api/customers HTTP/1.1" 200 OK
INFO:     127.0.0.1:63176 - "GET /api/customers HTTP/1.1" 200 OK
INFO:     127.0.0.1:63176 - "GET /api/customers HTTP/1.1" 200 OK
INFO:     127.0.0.1:63179 - "OPTIONS /api/business/profile HTTP/1.1" 200 OK
INFO:     127.0.0.1:63194 - "OPTIONS /api/business/profile HTTP/1.1" 200 OK
INFO:     127.0.0.1:63179 - "GET /api/business/profile HTTP/1.1" 404 Not Found
INFO:     127.0.0.1:63179 - "GET /api/business/profile HTTP/1.1" 404 Not Found
INFO:     127.0.0.1:63196 - "OPTIONS /api/ai/enhanced-voice-processing HTTP/1.1" 200 OK
INFO:     127.0.0.1:63196 - "POST /api/ai/enhanced-voice-processing HTTP/1.1" 200 OK
INFO:     127.0.0.1:63204 - "OPTIONS /api/customers HTTP/1.1" 200 OK
INFO:     127.0.0.1:63204 - "POST /api/customers HTTP/1.1" 200 OK
INFO:     127.0.0.1:63204 - "OPTIONS /api/invoices HTTP/1.1" 200 OK
INFO:     127.0.0.1:63210 - "POST /api/invoices HTTP/1.1" 200 OK
INFO:     127.0.0.1:63210 - "GET /api/customers HTTP/1.1" 200 OK
INFO:     127.0.0.1:63210 - "GET /api/customers HTTP/1.1" 200 OK
INFO:     127.0.0.1:63227 - "GET /api/invoices HTTP/1.1" 200 OK
INFO:     127.0.0.1:63229 - "GET /api/invoices HTTP/1.1" 200 OK
INFO:     127.0.0.1:63237 - "OPTIONS /api/invoices/f8fe19b9-28cf-4d48-8cfb-613d8c7c870a/status HTTP/1.1" 200 OK
INFO:     127.0.0.1:63237 - "PATCH /api/invoices/f8fe19b9-28cf-4d48-8cfb-613d8c7c870a/status HTTP/1.1" 405 Method Not Allowed
INFO:     127.0.0.1:63239 - "GET /api/customers HTTP/1.1" 200 OK
INFO:     127.0.0.1:63239 - "GET /api/customers HTTP/1.1" 200 OK
INFO:     127.0.0.1:63259 - "POST /api/ai/enhanced-voice-processing HTTP/1.1" 200 OK
INFO:     127.0.0.1:63259 - "POST /api/invoices HTTP/1.1" 200 OK
INFO:     127.0.0.1:63268 - "GET /api/invoices HTTP/1.1" 200 OK
INFO:     127.0.0.1:63268 - "GET /api/invoices HTTP/1.1" 200 OK
INFO:     127.0.0.1:63278 - "GET /api/business/profile HTTP/1.1" 404 Not Found
INFO:     127.0.0.1:63278 - "GET /api/business/profile HTTP/1.1" 404 Not Found
INFO:     127.0.0.1:63293 - "OPTIONS /api/business/profile HTTP/1.1" 200 OK
INFO:     127.0.0.1:63293 - "POST /api/business/profile HTTP/1.1" 200 OK
INFO:     127.0.0.1:63293 - "OPTIONS /api/business/generate-template HTTP/1.1" 200 OK
INFO:     127.0.0.1:63295 - "POST /api/business/generate-template HTTP/1.1" 500 Internal Server Error
ERROR:    Exception in ASGI application
Traceback (most recent call last):
  File "/Users/quick/Desktop/bill_generator-main/backend/venv/lib/python3.13/site-packages/fastapi/encoders.py", line 322, in jsonable_encoder
    data = dict(obj)
TypeError: 'ObjectId' object is not iterable

During handling of the above exception, another exception occurred:

Traceback (most recent call last):
  File "/Users/quick/Desktop/bill_generator-main/backend/venv/lib/python3.13/site-packages/fastapi/encoders.py", line 327, in jsonable_encoder
    data = vars(obj)
TypeError: vars() argument must have __dict__ attribute

The above exception was the direct cause of the following exception:

Traceback (most recent call last):
  File "/Users/quick/Desktop/bill_generator-main/backend/venv/lib/python3.13/site-packages/uvicorn/protocols/http/h11_impl.py", line 408, in run_asgi
    result = await app(  # type: ignore[func-returns-value]
             ^^^^^^^^^^^^^^^^^^^^^^^^^^^^^^^^^^^^^^^^^^^^^^
        self.scope, self.receive, self.send
        ^^^^^^^^^^^^^^^^^^^^^^^^^^^^^^^^^^^
    )
    ^
  File "/Users/quick/Desktop/bill_generator-main/backend/venv/lib/python3.13/site-packages/uvicorn/middleware/proxy_headers.py", line 84, in __call__
    return await self.app(scope, receive, send)
           ^^^^^^^^^^^^^^^^^^^^^^^^^^^^^^^^^^^^
  File "/Users/quick/Desktop/bill_generator-main/backend/venv/lib/python3.13/site-packages/fastapi/applications.py", line 1054, in __call__
    await super().__call__(scope, receive, send)
  File "/Users/quick/Desktop/bill_generator-main/backend/venv/lib/python3.13/site-packages/starlette/applications.py", line 123, in __call__
    await self.middleware_stack(scope, receive, send)
  File "/Users/quick/Desktop/bill_generator-main/backend/venv/lib/python3.13/site-packages/starlette/middleware/errors.py", line 186, in __call__
    raise exc
  File "/Users/quick/Desktop/bill_generator-main/backend/venv/lib/python3.13/site-packages/starlette/middleware/errors.py", line 164, in __call__
    await self.app(scope, receive, _send)
  File "/Users/quick/Desktop/bill_generator-main/backend/venv/lib/python3.13/site-packages/starlette/middleware/cors.py", line 93, in __call__
    await self.simple_response(scope, receive, send, request_headers=headers)
  File "/Users/quick/Desktop/bill_generator-main/backend/venv/lib/python3.13/site-packages/starlette/middleware/cors.py", line 148, in simple_response
    await self.app(scope, receive, send)
  File "/Users/quick/Desktop/bill_generator-main/backend/venv/lib/python3.13/site-packages/starlette/middleware/exceptions.py", line 65, in __call__
    await wrap_app_handling_exceptions(self.app, conn)(scope, receive, send)
  File "/Users/quick/Desktop/bill_generator-main/backend/venv/lib/python3.13/site-packages/starlette/_exception_handler.py", line 64, in wrapped_app
    raise exc
  File "/Users/quick/Desktop/bill_generator-main/backend/venv/lib/python3.13/site-packages/starlette/_exception_handler.py", line 53, in wrapped_app
    await app(scope, receive, sender)
  File "/Users/quick/Desktop/bill_generator-main/backend/venv/lib/python3.13/site-packages/starlette/routing.py", line 756, in __call__
    await self.middleware_stack(scope, receive, send)
  File "/Users/quick/Desktop/bill_generator-main/backend/venv/lib/python3.13/site-packages/starlette/routing.py", line 776, in app
    await route.handle(scope, receive, send)
  File "/Users/quick/Desktop/bill_generator-main/backend/venv/lib/python3.13/site-packages/starlette/routing.py", line 297, in handle
    await self.app(scope, receive, send)
  File "/Users/quick/Desktop/bill_generator-main/backend/venv/lib/python3.13/site-packages/starlette/routing.py", line 77, in app
    await wrap_app_handling_exceptions(app, request)(scope, receive, send)
  File "/Users/quick/Desktop/bill_generator-main/backend/venv/lib/python3.13/site-packages/starlette/_exception_handler.py", line 64, in wrapped_app
    raise exc
  File "/Users/quick/Desktop/bill_generator-main/backend/venv/lib/python3.13/site-packages/starlette/_exception_handler.py", line 53, in wrapped_app
    await app(scope, receive, sender)
  File "/Users/quick/Desktop/bill_generator-main/backend/venv/lib/python3.13/site-packages/starlette/routing.py", line 72, in app
    response = await func(request)
               ^^^^^^^^^^^^^^^^^^^
  File "/Users/quick/Desktop/bill_generator-main/backend/venv/lib/python3.13/site-packages/fastapi/routing.py", line 296, in app
    content = await serialize_response(
              ^^^^^^^^^^^^^^^^^^^^^^^^^
    ...<9 lines>...
    )
    ^
  File "/Users/quick/Desktop/bill_generator-main/backend/venv/lib/python3.13/site-packages/fastapi/routing.py", line 180, in serialize_response
    return jsonable_encoder(response_content)
  File "/Users/quick/Desktop/bill_generator-main/backend/venv/lib/python3.13/site-packages/fastapi/encoders.py", line 287, in jsonable_encoder
    encoded_value = jsonable_encoder(
        value,
    ...<4 lines>...
        sqlalchemy_safe=sqlalchemy_safe,
    )
  File "/Users/quick/Desktop/bill_generator-main/backend/venv/lib/python3.13/site-packages/fastapi/encoders.py", line 287, in jsonable_encoder
    encoded_value = jsonable_encoder(
        value,
    ...<4 lines>...
        sqlalchemy_safe=sqlalchemy_safe,
    )
  File "/Users/quick/Desktop/bill_generator-main/backend/venv/lib/python3.13/site-packages/fastapi/encoders.py", line 330, in jsonable_encoder
    raise ValueError(errors) from e
ValueError: [TypeError("'ObjectId' object is not iterable"), TypeError('vars() argument must have __dict__ attribute')]
INFO:     127.0.0.1:63293 - "POST /api/business/profile HTTP/1.1" 200 OK
INFO:     127.0.0.1:63293 - "POST /api/business/profile HTTP/1.1" 200 OK
INFO:     127.0.0.1:63293 - "POST /api/business/profile HTTP/1.1" 200 OK
INFO:     127.0.0.1:63293 - "POST /api/business/profile HTTP/1.1" 200 OK
INFO:     127.0.0.1:63293 - "POST /api/business/profile HTTP/1.1" 200 OK
INFO:     127.0.0.1:63293 - "POST /api/business/profile HTTP/1.1" 200 OK
INFO:     127.0.0.1:63293 - "POST /api/business/profile HTTP/1.1" 200 OK
INFO:     127.0.0.1:63293 - "POST /api/business/profile HTTP/1.1" 200 OK
INFO:     127.0.0.1:63293 - "POST /api/business/generate-template HTTP/1.1" 500 Internal Server Error
ERROR:    Exception in ASGI application
Traceback (most recent call last):
  File "/Users/quick/Desktop/bill_generator-main/backend/venv/lib/python3.13/site-packages/fastapi/encoders.py", line 322, in jsonable_encoder
    data = dict(obj)
TypeError: 'ObjectId' object is not iterable

During handling of the above exception, another exception occurred:

Traceback (most recent call last):
  File "/Users/quick/Desktop/bill_generator-main/backend/venv/lib/python3.13/site-packages/fastapi/encoders.py", line 327, in jsonable_encoder
    data = vars(obj)
TypeError: vars() argument must have __dict__ attribute

The above exception was the direct cause of the following exception:

Traceback (most recent call last):
  File "/Users/quick/Desktop/bill_generator-main/backend/venv/lib/python3.13/site-packages/uvicorn/protocols/http/h11_impl.py", line 408, in run_asgi
    result = await app(  # type: ignore[func-returns-value]
             ^^^^^^^^^^^^^^^^^^^^^^^^^^^^^^^^^^^^^^^^^^^^^^
        self.scope, self.receive, self.send
        ^^^^^^^^^^^^^^^^^^^^^^^^^^^^^^^^^^^
    )
    ^
  File "/Users/quick/Desktop/bill_generator-main/backend/venv/lib/python3.13/site-packages/uvicorn/middleware/proxy_headers.py", line 84, in __call__
    return await self.app(scope, receive, send)
           ^^^^^^^^^^^^^^^^^^^^^^^^^^^^^^^^^^^^
  File "/Users/quick/Desktop/bill_generator-main/backend/venv/lib/python3.13/site-packages/fastapi/applications.py", line 1054, in __call__
    await super().__call__(scope, receive, send)
  File "/Users/quick/Desktop/bill_generator-main/backend/venv/lib/python3.13/site-packages/starlette/applications.py", line 123, in __call__
    await self.middleware_stack(scope, receive, send)
  File "/Users/quick/Desktop/bill_generator-main/backend/venv/lib/python3.13/site-packages/starlette/middleware/errors.py", line 186, in __call__
    raise exc
  File "/Users/quick/Desktop/bill_generator-main/backend/venv/lib/python3.13/site-packages/starlette/middleware/errors.py", line 164, in __call__
    await self.app(scope, receive, _send)
  File "/Users/quick/Desktop/bill_generator-main/backend/venv/lib/python3.13/site-packages/starlette/middleware/cors.py", line 93, in __call__
    await self.simple_response(scope, receive, send, request_headers=headers)
  File "/Users/quick/Desktop/bill_generator-main/backend/venv/lib/python3.13/site-packages/starlette/middleware/cors.py", line 148, in simple_response
    await self.app(scope, receive, send)
  File "/Users/quick/Desktop/bill_generator-main/backend/venv/lib/python3.13/site-packages/starlette/middleware/exceptions.py", line 65, in __call__
    await wrap_app_handling_exceptions(self.app, conn)(scope, receive, send)
  File "/Users/quick/Desktop/bill_generator-main/backend/venv/lib/python3.13/site-packages/starlette/_exception_handler.py", line 64, in wrapped_app
    raise exc
  File "/Users/quick/Desktop/bill_generator-main/backend/venv/lib/python3.13/site-packages/starlette/_exception_handler.py", line 53, in wrapped_app
    await app(scope, receive, sender)
  File "/Users/quick/Desktop/bill_generator-main/backend/venv/lib/python3.13/site-packages/starlette/routing.py", line 756, in __call__
    await self.middleware_stack(scope, receive, send)
  File "/Users/quick/Desktop/bill_generator-main/backend/venv/lib/python3.13/site-packages/starlette/routing.py", line 776, in app
    await route.handle(scope, receive, send)
  File "/Users/quick/Desktop/bill_generator-main/backend/venv/lib/python3.13/site-packages/starlette/routing.py", line 297, in handle
    await self.app(scope, receive, send)
  File "/Users/quick/Desktop/bill_generator-main/backend/venv/lib/python3.13/site-packages/starlette/routing.py", line 77, in app
    await wrap_app_handling_exceptions(app, request)(scope, receive, send)
  File "/Users/quick/Desktop/bill_generator-main/backend/venv/lib/python3.13/site-packages/starlette/_exception_handler.py", line 64, in wrapped_app
    raise exc
  File "/Users/quick/Desktop/bill_generator-main/backend/venv/lib/python3.13/site-packages/starlette/_exception_handler.py", line 53, in wrapped_app
    await app(scope, receive, sender)
  File "/Users/quick/Desktop/bill_generator-main/backend/venv/lib/python3.13/site-packages/starlette/routing.py", line 72, in app
    response = await func(request)
               ^^^^^^^^^^^^^^^^^^^
  File "/Users/quick/Desktop/bill_generator-main/backend/venv/lib/python3.13/site-packages/fastapi/routing.py", line 296, in app
    content = await serialize_response(
              ^^^^^^^^^^^^^^^^^^^^^^^^^
    ...<9 lines>...
    )
    ^
  File "/Users/quick/Desktop/bill_generator-main/backend/venv/lib/python3.13/site-packages/fastapi/routing.py", line 180, in serialize_response
    return jsonable_encoder(response_content)
  File "/Users/quick/Desktop/bill_generator-main/backend/venv/lib/python3.13/site-packages/fastapi/encoders.py", line 287, in jsonable_encoder
    encoded_value = jsonable_encoder(
        value,
    ...<4 lines>...
        sqlalchemy_safe=sqlalchemy_safe,
    )
  File "/Users/quick/Desktop/bill_generator-main/backend/venv/lib/python3.13/site-packages/fastapi/encoders.py", line 287, in jsonable_encoder
    encoded_value = jsonable_encoder(
        value,
    ...<4 lines>...
        sqlalchemy_safe=sqlalchemy_safe,
    )
  File "/Users/quick/Desktop/bill_generator-main/backend/venv/lib/python3.13/site-packages/fastapi/encoders.py", line 330, in jsonable_encoder
    raise ValueError(errors) from e
ValueError: [TypeError("'ObjectId' object is not iterable"), TypeError('vars() argument must have __dict__ attribute')]
INFO:     127.0.0.1:63301 - "POST /api/business/profile HTTP/1.1" 200 OK
INFO:     127.0.0.1:63301 - "POST /api/business/generate-template HTTP/1.1" 500 Internal Server Error
ERROR:    Exception in ASGI application
Traceback (most recent call last):
  File "/Users/quick/Desktop/bill_generator-main/backend/venv/lib/python3.13/site-packages/fastapi/encoders.py", line 322, in jsonable_encoder
    data = dict(obj)
TypeError: 'ObjectId' object is not iterable

During handling of the above exception, another exception occurred:

Traceback (most recent call last):
  File "/Users/quick/Desktop/bill_generator-main/backend/venv/lib/python3.13/site-packages/fastapi/encoders.py", line 327, in jsonable_encoder
    data = vars(obj)
TypeError: vars() argument must have __dict__ attribute

The above exception was the direct cause of the following exception:

Traceback (most recent call last):
  File "/Users/quick/Desktop/bill_generator-main/backend/venv/lib/python3.13/site-packages/uvicorn/protocols/http/h11_impl.py", line 408, in run_asgi
    result = await app(  # type: ignore[func-returns-value]
             ^^^^^^^^^^^^^^^^^^^^^^^^^^^^^^^^^^^^^^^^^^^^^^
        self.scope, self.receive, self.send
        ^^^^^^^^^^^^^^^^^^^^^^^^^^^^^^^^^^^
    )
    ^
  File "/Users/quick/Desktop/bill_generator-main/backend/venv/lib/python3.13/site-packages/uvicorn/middleware/proxy_headers.py", line 84, in __call__
    return await self.app(scope, receive, send)
           ^^^^^^^^^^^^^^^^^^^^^^^^^^^^^^^^^^^^
  File "/Users/quick/Desktop/bill_generator-main/backend/venv/lib/python3.13/site-packages/fastapi/applications.py", line 1054, in __call__
    await super().__call__(scope, receive, send)
  File "/Users/quick/Desktop/bill_generator-main/backend/venv/lib/python3.13/site-packages/starlette/applications.py", line 123, in __call__
    await self.middleware_stack(scope, receive, send)
  File "/Users/quick/Desktop/bill_generator-main/backend/venv/lib/python3.13/site-packages/starlette/middleware/errors.py", line 186, in __call__
    raise exc
  File "/Users/quick/Desktop/bill_generator-main/backend/venv/lib/python3.13/site-packages/starlette/middleware/errors.py", line 164, in __call__
    await self.app(scope, receive, _send)
  File "/Users/quick/Desktop/bill_generator-main/backend/venv/lib/python3.13/site-packages/starlette/middleware/cors.py", line 93, in __call__
    await self.simple_response(scope, receive, send, request_headers=headers)
  File "/Users/quick/Desktop/bill_generator-main/backend/venv/lib/python3.13/site-packages/starlette/middleware/cors.py", line 148, in simple_response
    await self.app(scope, receive, send)
  File "/Users/quick/Desktop/bill_generator-main/backend/venv/lib/python3.13/site-packages/starlette/middleware/exceptions.py", line 65, in __call__
    await wrap_app_handling_exceptions(self.app, conn)(scope, receive, send)
  File "/Users/quick/Desktop/bill_generator-main/backend/venv/lib/python3.13/site-packages/starlette/_exception_handler.py", line 64, in wrapped_app
    raise exc
  File "/Users/quick/Desktop/bill_generator-main/backend/venv/lib/python3.13/site-packages/starlette/_exception_handler.py", line 53, in wrapped_app
    await app(scope, receive, sender)
  File "/Users/quick/Desktop/bill_generator-main/backend/venv/lib/python3.13/site-packages/starlette/routing.py", line 756, in __call__
    await self.middleware_stack(scope, receive, send)
  File "/Users/quick/Desktop/bill_generator-main/backend/venv/lib/python3.13/site-packages/starlette/routing.py", line 776, in app
    await route.handle(scope, receive, send)
  File "/Users/quick/Desktop/bill_generator-main/backend/venv/lib/python3.13/site-packages/starlette/routing.py", line 297, in handle
    await self.app(scope, receive, send)
  File "/Users/quick/Desktop/bill_generator-main/backend/venv/lib/python3.13/site-packages/starlette/routing.py", line 77, in app
    await wrap_app_handling_exceptions(app, request)(scope, receive, send)
  File "/Users/quick/Desktop/bill_generator-main/backend/venv/lib/python3.13/site-packages/starlette/_exception_handler.py", line 64, in wrapped_app
    raise exc
  File "/Users/quick/Desktop/bill_generator-main/backend/venv/lib/python3.13/site-packages/starlette/_exception_handler.py", line 53, in wrapped_app
    await app(scope, receive, sender)
  File "/Users/quick/Desktop/bill_generator-main/backend/venv/lib/python3.13/site-packages/starlette/routing.py", line 72, in app
    response = await func(request)
               ^^^^^^^^^^^^^^^^^^^
  File "/Users/quick/Desktop/bill_generator-main/backend/venv/lib/python3.13/site-packages/fastapi/routing.py", line 296, in app
    content = await serialize_response(
              ^^^^^^^^^^^^^^^^^^^^^^^^^
    ...<9 lines>...
    )
    ^
  File "/Users/quick/Desktop/bill_generator-main/backend/venv/lib/python3.13/site-packages/fastapi/routing.py", line 180, in serialize_response
    return jsonable_encoder(response_content)
  File "/Users/quick/Desktop/bill_generator-main/backend/venv/lib/python3.13/site-packages/fastapi/encoders.py", line 287, in jsonable_encoder
    encoded_value = jsonable_encoder(
        value,
    ...<4 lines>...
        sqlalchemy_safe=sqlalchemy_safe,
    )
  File "/Users/quick/Desktop/bill_generator-main/backend/venv/lib/python3.13/site-packages/fastapi/encoders.py", line 287, in jsonable_encoder
    encoded_value = jsonable_encoder(
        value,
    ...<4 lines>...
        sqlalchemy_safe=sqlalchemy_safe,
    )
  File "/Users/quick/Desktop/bill_generator-main/backend/venv/lib/python3.13/site-packages/fastapi/encoders.py", line 330, in jsonable_encoder
    raise ValueError(errors) from e
ValueError: [TypeError("'ObjectId' object is not iterable"), TypeError('vars() argument must have __dict__ attribute')]
INFO:     127.0.0.1:63303 - "POST /api/business/profile HTTP/1.1" 200 OK
INFO:     127.0.0.1:63303 - "POST /api/business/generate-template HTTP/1.1" 500 Internal Server Error
ERROR:    Exception in ASGI application
Traceback (most recent call last):
  File "/Users/quick/Desktop/bill_generator-main/backend/venv/lib/python3.13/site-packages/fastapi/encoders.py", line 322, in jsonable_encoder
    data = dict(obj)
TypeError: 'ObjectId' object is not iterable

During handling of the above exception, another exception occurred:

Traceback (most recent call last):
  File "/Users/quick/Desktop/bill_generator-main/backend/venv/lib/python3.13/site-packages/fastapi/encoders.py", line 327, in jsonable_encoder
    data = vars(obj)
TypeError: vars() argument must have __dict__ attribute

The above exception was the direct cause of the following exception:

Traceback (most recent call last):
  File "/Users/quick/Desktop/bill_generator-main/backend/venv/lib/python3.13/site-packages/uvicorn/protocols/http/h11_impl.py", line 408, in run_asgi
    result = await app(  # type: ignore[func-returns-value]
             ^^^^^^^^^^^^^^^^^^^^^^^^^^^^^^^^^^^^^^^^^^^^^^
        self.scope, self.receive, self.send
        ^^^^^^^^^^^^^^^^^^^^^^^^^^^^^^^^^^^
    )
    ^
  File "/Users/quick/Desktop/bill_generator-main/backend/venv/lib/python3.13/site-packages/uvicorn/middleware/proxy_headers.py", line 84, in __call__
    return await self.app(scope, receive, send)
           ^^^^^^^^^^^^^^^^^^^^^^^^^^^^^^^^^^^^
  File "/Users/quick/Desktop/bill_generator-main/backend/venv/lib/python3.13/site-packages/fastapi/applications.py", line 1054, in __call__
    await super().__call__(scope, receive, send)
  File "/Users/quick/Desktop/bill_generator-main/backend/venv/lib/python3.13/site-packages/starlette/applications.py", line 123, in __call__
    await self.middleware_stack(scope, receive, send)
  File "/Users/quick/Desktop/bill_generator-main/backend/venv/lib/python3.13/site-packages/starlette/middleware/errors.py", line 186, in __call__
    raise exc
  File "/Users/quick/Desktop/bill_generator-main/backend/venv/lib/python3.13/site-packages/starlette/middleware/errors.py", line 164, in __call__
    await self.app(scope, receive, _send)
  File "/Users/quick/Desktop/bill_generator-main/backend/venv/lib/python3.13/site-packages/starlette/middleware/cors.py", line 93, in __call__
    await self.simple_response(scope, receive, send, request_headers=headers)
  File "/Users/quick/Desktop/bill_generator-main/backend/venv/lib/python3.13/site-packages/starlette/middleware/cors.py", line 148, in simple_response
    await self.app(scope, receive, send)
  File "/Users/quick/Desktop/bill_generator-main/backend/venv/lib/python3.13/site-packages/starlette/middleware/exceptions.py", line 65, in __call__
    await wrap_app_handling_exceptions(self.app, conn)(scope, receive, send)
  File "/Users/quick/Desktop/bill_generator-main/backend/venv/lib/python3.13/site-packages/starlette/_exception_handler.py", line 64, in wrapped_app
    raise exc
  File "/Users/quick/Desktop/bill_generator-main/backend/venv/lib/python3.13/site-packages/starlette/_exception_handler.py", line 53, in wrapped_app
    await app(scope, receive, sender)
  File "/Users/quick/Desktop/bill_generator-main/backend/venv/lib/python3.13/site-packages/starlette/routing.py", line 756, in __call__
    await self.middleware_stack(scope, receive, send)
  File "/Users/quick/Desktop/bill_generator-main/backend/venv/lib/python3.13/site-packages/starlette/routing.py", line 776, in app
    await route.handle(scope, receive, send)
  File "/Users/quick/Desktop/bill_generator-main/backend/venv/lib/python3.13/site-packages/starlette/routing.py", line 297, in handle
    await self.app(scope, receive, send)
  File "/Users/quick/Desktop/bill_generator-main/backend/venv/lib/python3.13/site-packages/starlette/routing.py", line 77, in app
    await wrap_app_handling_exceptions(app, request)(scope, receive, send)
  File "/Users/quick/Desktop/bill_generator-main/backend/venv/lib/python3.13/site-packages/starlette/_exception_handler.py", line 64, in wrapped_app
    raise exc
  File "/Users/quick/Desktop/bill_generator-main/backend/venv/lib/python3.13/site-packages/starlette/_exception_handler.py", line 53, in wrapped_app
    await app(scope, receive, sender)
  File "/Users/quick/Desktop/bill_generator-main/backend/venv/lib/python3.13/site-packages/starlette/routing.py", line 72, in app
    response = await func(request)
               ^^^^^^^^^^^^^^^^^^^
  File "/Users/quick/Desktop/bill_generator-main/backend/venv/lib/python3.13/site-packages/fastapi/routing.py", line 296, in app
    content = await serialize_response(
              ^^^^^^^^^^^^^^^^^^^^^^^^^
    ...<9 lines>...
    )
    ^
  File "/Users/quick/Desktop/bill_generator-main/backend/venv/lib/python3.13/site-packages/fastapi/routing.py", line 180, in serialize_response
    return jsonable_encoder(response_content)
  File "/Users/quick/Desktop/bill_generator-main/backend/venv/lib/python3.13/site-packages/fastapi/encoders.py", line 287, in jsonable_encoder
    encoded_value = jsonable_encoder(
        value,
    ...<4 lines>...
        sqlalchemy_safe=sqlalchemy_safe,
    )
  File "/Users/quick/Desktop/bill_generator-main/backend/venv/lib/python3.13/site-packages/fastapi/encoders.py", line 287, in jsonable_encoder
    encoded_value = jsonable_encoder(
        value,
    ...<4 lines>...
        sqlalchemy_safe=sqlalchemy_safe,
    )
  File "/Users/quick/Desktop/bill_generator-main/backend/venv/lib/python3.13/site-packages/fastapi/encoders.py", line 330, in jsonable_encoder
    raise ValueError(errors) from e
ValueError: [TypeError("'ObjectId' object is not iterable"), TypeError('vars() argument must have __dict__ attribute')]
INFO:     127.0.0.1:63305 - "POST /api/business/profile HTTP/1.1" 200 OK
INFO:     127.0.0.1:63305 - "POST /api/business/generate-template HTTP/1.1" 500 Internal Server Error
ERROR:    Exception in ASGI application
Traceback (most recent call last):
  File "/Users/quick/Desktop/bill_generator-main/backend/venv/lib/python3.13/site-packages/fastapi/encoders.py", line 322, in jsonable_encoder
    data = dict(obj)
TypeError: 'ObjectId' object is not iterable

During handling of the above exception, another exception occurred:

Traceback (most recent call last):
  File "/Users/quick/Desktop/bill_generator-main/backend/venv/lib/python3.13/site-packages/fastapi/encoders.py", line 327, in jsonable_encoder
    data = vars(obj)
TypeError: vars() argument must have __dict__ attribute

The above exception was the direct cause of the following exception:

Traceback (most recent call last):
  File "/Users/quick/Desktop/bill_generator-main/backend/venv/lib/python3.13/site-packages/uvicorn/protocols/http/h11_impl.py", line 408, in run_asgi
    result = await app(  # type: ignore[func-returns-value]
             ^^^^^^^^^^^^^^^^^^^^^^^^^^^^^^^^^^^^^^^^^^^^^^
        self.scope, self.receive, self.send
        ^^^^^^^^^^^^^^^^^^^^^^^^^^^^^^^^^^^
    )
    ^
  File "/Users/quick/Desktop/bill_generator-main/backend/venv/lib/python3.13/site-packages/uvicorn/middleware/proxy_headers.py", line 84, in __call__
    return await self.app(scope, receive, send)
           ^^^^^^^^^^^^^^^^^^^^^^^^^^^^^^^^^^^^
  File "/Users/quick/Desktop/bill_generator-main/backend/venv/lib/python3.13/site-packages/fastapi/applications.py", line 1054, in __call__
    await super().__call__(scope, receive, send)
  File "/Users/quick/Desktop/bill_generator-main/backend/venv/lib/python3.13/site-packages/starlette/applications.py", line 123, in __call__
    await self.middleware_stack(scope, receive, send)
  File "/Users/quick/Desktop/bill_generator-main/backend/venv/lib/python3.13/site-packages/starlette/middleware/errors.py", line 186, in __call__
    raise exc
  File "/Users/quick/Desktop/bill_generator-main/backend/venv/lib/python3.13/site-packages/starlette/middleware/errors.py", line 164, in __call__
    await self.app(scope, receive, _send)
  File "/Users/quick/Desktop/bill_generator-main/backend/venv/lib/python3.13/site-packages/starlette/middleware/cors.py", line 93, in __call__
    await self.simple_response(scope, receive, send, request_headers=headers)
  File "/Users/quick/Desktop/bill_generator-main/backend/venv/lib/python3.13/site-packages/starlette/middleware/cors.py", line 148, in simple_response
    await self.app(scope, receive, send)
  File "/Users/quick/Desktop/bill_generator-main/backend/venv/lib/python3.13/site-packages/starlette/middleware/exceptions.py", line 65, in __call__
    await wrap_app_handling_exceptions(self.app, conn)(scope, receive, send)
  File "/Users/quick/Desktop/bill_generator-main/backend/venv/lib/python3.13/site-packages/starlette/_exception_handler.py", line 64, in wrapped_app
    raise exc
  File "/Users/quick/Desktop/bill_generator-main/backend/venv/lib/python3.13/site-packages/starlette/_exception_handler.py", line 53, in wrapped_app
    await app(scope, receive, sender)
  File "/Users/quick/Desktop/bill_generator-main/backend/venv/lib/python3.13/site-packages/starlette/routing.py", line 756, in __call__
    await self.middleware_stack(scope, receive, send)
  File "/Users/quick/Desktop/bill_generator-main/backend/venv/lib/python3.13/site-packages/starlette/routing.py", line 776, in app
    await route.handle(scope, receive, send)
  File "/Users/quick/Desktop/bill_generator-main/backend/venv/lib/python3.13/site-packages/starlette/routing.py", line 297, in handle
    await self.app(scope, receive, send)
  File "/Users/quick/Desktop/bill_generator-main/backend/venv/lib/python3.13/site-packages/starlette/routing.py", line 77, in app
    await wrap_app_handling_exceptions(app, request)(scope, receive, send)
  File "/Users/quick/Desktop/bill_generator-main/backend/venv/lib/python3.13/site-packages/starlette/_exception_handler.py", line 64, in wrapped_app
    raise exc
  File "/Users/quick/Desktop/bill_generator-main/backend/venv/lib/python3.13/site-packages/starlette/_exception_handler.py", line 53, in wrapped_app
    await app(scope, receive, sender)
  File "/Users/quick/Desktop/bill_generator-main/backend/venv/lib/python3.13/site-packages/starlette/routing.py", line 72, in app
    response = await func(request)
               ^^^^^^^^^^^^^^^^^^^
  File "/Users/quick/Desktop/bill_generator-main/backend/venv/lib/python3.13/site-packages/fastapi/routing.py", line 296, in app
    content = await serialize_response(
              ^^^^^^^^^^^^^^^^^^^^^^^^^
    ...<9 lines>...
    )
    ^
  File "/Users/quick/Desktop/bill_generator-main/backend/venv/lib/python3.13/site-packages/fastapi/routing.py", line 180, in serialize_response
    return jsonable_encoder(response_content)
  File "/Users/quick/Desktop/bill_generator-main/backend/venv/lib/python3.13/site-packages/fastapi/encoders.py", line 287, in jsonable_encoder
    encoded_value = jsonable_encoder(
        value,
    ...<4 lines>...
        sqlalchemy_safe=sqlalchemy_safe,
    )
  File "/Users/quick/Desktop/bill_generator-main/backend/venv/lib/python3.13/site-packages/fastapi/encoders.py", line 287, in jsonable_encoder
    encoded_value = jsonable_encoder(
        value,
    ...<4 lines>...
        sqlalchemy_safe=sqlalchemy_safe,
    )
  File "/Users/quick/Desktop/bill_generator-main/backend/venv/lib/python3.13/site-packages/fastapi/encoders.py", line 330, in jsonable_encoder
    raise ValueError(errors) from e
ValueError: [TypeError("'ObjectId' object is not iterable"), TypeError('vars() argument must have __dict__ attribute')]
INFO:     127.0.0.1:63307 - "POST /api/business/profile HTTP/1.1" 200 OK
INFO:     127.0.0.1:63307 - "POST /api/business/generate-template HTTP/1.1" 500 Internal Server Error
ERROR:    Exception in ASGI application
Traceback (most recent call last):
  File "/Users/quick/Desktop/bill_generator-main/backend/venv/lib/python3.13/site-packages/fastapi/encoders.py", line 322, in jsonable_encoder
    data = dict(obj)
TypeError: 'ObjectId' object is not iterable

During handling of the above exception, another exception occurred:

Traceback (most recent call last):
  File "/Users/quick/Desktop/bill_generator-main/backend/venv/lib/python3.13/site-packages/fastapi/encoders.py", line 327, in jsonable_encoder
    data = vars(obj)
TypeError: vars() argument must have __dict__ attribute

The above exception was the direct cause of the following exception:

Traceback (most recent call last):
  File "/Users/quick/Desktop/bill_generator-main/backend/venv/lib/python3.13/site-packages/uvicorn/protocols/http/h11_impl.py", line 408, in run_asgi
    result = await app(  # type: ignore[func-returns-value]
             ^^^^^^^^^^^^^^^^^^^^^^^^^^^^^^^^^^^^^^^^^^^^^^
        self.scope, self.receive, self.send
        ^^^^^^^^^^^^^^^^^^^^^^^^^^^^^^^^^^^
    )
    ^
  File "/Users/quick/Desktop/bill_generator-main/backend/venv/lib/python3.13/site-packages/uvicorn/middleware/proxy_headers.py", line 84, in __call__
    return await self.app(scope, receive, send)
           ^^^^^^^^^^^^^^^^^^^^^^^^^^^^^^^^^^^^
  File "/Users/quick/Desktop/bill_generator-main/backend/venv/lib/python3.13/site-packages/fastapi/applications.py", line 1054, in __call__
    await super().__call__(scope, receive, send)
  File "/Users/quick/Desktop/bill_generator-main/backend/venv/lib/python3.13/site-packages/starlette/applications.py", line 123, in __call__
    await self.middleware_stack(scope, receive, send)
  File "/Users/quick/Desktop/bill_generator-main/backend/venv/lib/python3.13/site-packages/starlette/middleware/errors.py", line 186, in __call__
    raise exc
  File "/Users/quick/Desktop/bill_generator-main/backend/venv/lib/python3.13/site-packages/starlette/middleware/errors.py", line 164, in __call__
    await self.app(scope, receive, _send)
  File "/Users/quick/Desktop/bill_generator-main/backend/venv/lib/python3.13/site-packages/starlette/middleware/cors.py", line 93, in __call__
    await self.simple_response(scope, receive, send, request_headers=headers)
  File "/Users/quick/Desktop/bill_generator-main/backend/venv/lib/python3.13/site-packages/starlette/middleware/cors.py", line 148, in simple_response
    await self.app(scope, receive, send)
  File "/Users/quick/Desktop/bill_generator-main/backend/venv/lib/python3.13/site-packages/starlette/middleware/exceptions.py", line 65, in __call__
    await wrap_app_handling_exceptions(self.app, conn)(scope, receive, send)
  File "/Users/quick/Desktop/bill_generator-main/backend/venv/lib/python3.13/site-packages/starlette/_exception_handler.py", line 64, in wrapped_app
    raise exc
  File "/Users/quick/Desktop/bill_generator-main/backend/venv/lib/python3.13/site-packages/starlette/_exception_handler.py", line 53, in wrapped_app
    await app(scope, receive, sender)
  File "/Users/quick/Desktop/bill_generator-main/backend/venv/lib/python3.13/site-packages/starlette/routing.py", line 756, in __call__
    await self.middleware_stack(scope, receive, send)
  File "/Users/quick/Desktop/bill_generator-main/backend/venv/lib/python3.13/site-packages/starlette/routing.py", line 776, in app
    await route.handle(scope, receive, send)
  File "/Users/quick/Desktop/bill_generator-main/backend/venv/lib/python3.13/site-packages/starlette/routing.py", line 297, in handle
    await self.app(scope, receive, send)
  File "/Users/quick/Desktop/bill_generator-main/backend/venv/lib/python3.13/site-packages/starlette/routing.py", line 77, in app
    await wrap_app_handling_exceptions(app, request)(scope, receive, send)
  File "/Users/quick/Desktop/bill_generator-main/backend/venv/lib/python3.13/site-packages/starlette/_exception_handler.py", line 64, in wrapped_app
    raise exc
  File "/Users/quick/Desktop/bill_generator-main/backend/venv/lib/python3.13/site-packages/starlette/_exception_handler.py", line 53, in wrapped_app
    await app(scope, receive, sender)
  File "/Users/quick/Desktop/bill_generator-main/backend/venv/lib/python3.13/site-packages/starlette/routing.py", line 72, in app
    response = await func(request)
               ^^^^^^^^^^^^^^^^^^^
  File "/Users/quick/Desktop/bill_generator-main/backend/venv/lib/python3.13/site-packages/fastapi/routing.py", line 296, in app
    content = await serialize_response(
              ^^^^^^^^^^^^^^^^^^^^^^^^^
    ...<9 lines>...
    )
    ^
  File "/Users/quick/Desktop/bill_generator-main/backend/venv/lib/python3.13/site-packages/fastapi/routing.py", line 180, in serialize_response
    return jsonable_encoder(response_content)
  File "/Users/quick/Desktop/bill_generator-main/backend/venv/lib/python3.13/site-packages/fastapi/encoders.py", line 287, in jsonable_encoder
    encoded_value = jsonable_encoder(
        value,
    ...<4 lines>...
        sqlalchemy_safe=sqlalchemy_safe,
    )
  File "/Users/quick/Desktop/bill_generator-main/backend/venv/lib/python3.13/site-packages/fastapi/encoders.py", line 287, in jsonable_encoder
    encoded_value = jsonable_encoder(
        value,
    ...<4 lines>...
        sqlalchemy_safe=sqlalchemy_safe,
    )
  File "/Users/quick/Desktop/bill_generator-main/backend/venv/lib/python3.13/site-packages/fastapi/encoders.py", line 330, in jsonable_encoder
    raise ValueError(errors) from e
ValueError: [TypeError("'ObjectId' object is not iterable"), TypeError('vars() argument must have __dict__ attribute')]
INFO:     127.0.0.1:63310 - "GET /api/customers HTTP/1.1" 200 OK
INFO:     127.0.0.1:63310 - "GET /api/customers HTTP/1.1" 200 OK
INFO:     127.0.0.1:63318 - "GET /api/business/profile HTTP/1.1" 404 Not Found
INFO:     127.0.0.1:63318 - "GET /api/business/profile HTTP/1.1" 404 Not Found
INFO:     127.0.0.1:63341 - "POST /api/business/profile HTTP/1.1" 200 OK
INFO:     127.0.0.1:63341 - "POST /api/business/generate-template HTTP/1.1" 500 Internal Server Error
ERROR:    Exception in ASGI application
Traceback (most recent call last):
  File "/Users/quick/Desktop/bill_generator-main/backend/venv/lib/python3.13/site-packages/fastapi/encoders.py", line 322, in jsonable_encoder
    data = dict(obj)
TypeError: 'ObjectId' object is not iterable

During handling of the above exception, another exception occurred:

Traceback (most recent call last):
  File "/Users/quick/Desktop/bill_generator-main/backend/venv/lib/python3.13/site-packages/fastapi/encoders.py", line 327, in jsonable_encoder
    data = vars(obj)
TypeError: vars() argument must have __dict__ attribute

The above exception was the direct cause of the following exception:

Traceback (most recent call last):
  File "/Users/quick/Desktop/bill_generator-main/backend/venv/lib/python3.13/site-packages/uvicorn/protocols/http/h11_impl.py", line 408, in run_asgi
    result = await app(  # type: ignore[func-returns-value]
             ^^^^^^^^^^^^^^^^^^^^^^^^^^^^^^^^^^^^^^^^^^^^^^
        self.scope, self.receive, self.send
        ^^^^^^^^^^^^^^^^^^^^^^^^^^^^^^^^^^^
    )
    ^
  File "/Users/quick/Desktop/bill_generator-main/backend/venv/lib/python3.13/site-packages/uvicorn/middleware/proxy_headers.py", line 84, in __call__
    return await self.app(scope, receive, send)
           ^^^^^^^^^^^^^^^^^^^^^^^^^^^^^^^^^^^^
  File "/Users/quick/Desktop/bill_generator-main/backend/venv/lib/python3.13/site-packages/fastapi/applications.py", line 1054, in __call__
    await super().__call__(scope, receive, send)
  File "/Users/quick/Desktop/bill_generator-main/backend/venv/lib/python3.13/site-packages/starlette/applications.py", line 123, in __call__
    await self.middleware_stack(scope, receive, send)
  File "/Users/quick/Desktop/bill_generator-main/backend/venv/lib/python3.13/site-packages/starlette/middleware/errors.py", line 186, in __call__
    raise exc
  File "/Users/quick/Desktop/bill_generator-main/backend/venv/lib/python3.13/site-packages/starlette/middleware/errors.py", line 164, in __call__
    await self.app(scope, receive, _send)
  File "/Users/quick/Desktop/bill_generator-main/backend/venv/lib/python3.13/site-packages/starlette/middleware/cors.py", line 93, in __call__
    await self.simple_response(scope, receive, send, request_headers=headers)
  File "/Users/quick/Desktop/bill_generator-main/backend/venv/lib/python3.13/site-packages/starlette/middleware/cors.py", line 148, in simple_response
    await self.app(scope, receive, send)
  File "/Users/quick/Desktop/bill_generator-main/backend/venv/lib/python3.13/site-packages/starlette/middleware/exceptions.py", line 65, in __call__
    await wrap_app_handling_exceptions(self.app, conn)(scope, receive, send)
  File "/Users/quick/Desktop/bill_generator-main/backend/venv/lib/python3.13/site-packages/starlette/_exception_handler.py", line 64, in wrapped_app
    raise exc
  File "/Users/quick/Desktop/bill_generator-main/backend/venv/lib/python3.13/site-packages/starlette/_exception_handler.py", line 53, in wrapped_app
    await app(scope, receive, sender)
  File "/Users/quick/Desktop/bill_generator-main/backend/venv/lib/python3.13/site-packages/starlette/routing.py", line 756, in __call__
    await self.middleware_stack(scope, receive, send)
  File "/Users/quick/Desktop/bill_generator-main/backend/venv/lib/python3.13/site-packages/starlette/routing.py", line 776, in app
    await route.handle(scope, receive, send)
  File "/Users/quick/Desktop/bill_generator-main/backend/venv/lib/python3.13/site-packages/starlette/routing.py", line 297, in handle
    await self.app(scope, receive, send)
  File "/Users/quick/Desktop/bill_generator-main/backend/venv/lib/python3.13/site-packages/starlette/routing.py", line 77, in app
    await wrap_app_handling_exceptions(app, request)(scope, receive, send)
  File "/Users/quick/Desktop/bill_generator-main/backend/venv/lib/python3.13/site-packages/starlette/_exception_handler.py", line 64, in wrapped_app
    raise exc
  File "/Users/quick/Desktop/bill_generator-main/backend/venv/lib/python3.13/site-packages/starlette/_exception_handler.py", line 53, in wrapped_app
    await app(scope, receive, sender)
  File "/Users/quick/Desktop/bill_generator-main/backend/venv/lib/python3.13/site-packages/starlette/routing.py", line 72, in app
    response = await func(request)
               ^^^^^^^^^^^^^^^^^^^
  File "/Users/quick/Desktop/bill_generator-main/backend/venv/lib/python3.13/site-packages/fastapi/routing.py", line 296, in app
    content = await serialize_response(
              ^^^^^^^^^^^^^^^^^^^^^^^^^
    ...<9 lines>...
    )
    ^
  File "/Users/quick/Desktop/bill_generator-main/backend/venv/lib/python3.13/site-packages/fastapi/routing.py", line 180, in serialize_response
    return jsonable_encoder(response_content)
  File "/Users/quick/Desktop/bill_generator-main/backend/venv/lib/python3.13/site-packages/fastapi/encoders.py", line 287, in jsonable_encoder
    encoded_value = jsonable_encoder(
        value,
    ...<4 lines>...
        sqlalchemy_safe=sqlalchemy_safe,
    )
  File "/Users/quick/Desktop/bill_generator-main/backend/venv/lib/python3.13/site-packages/fastapi/encoders.py", line 287, in jsonable_encoder
    encoded_value = jsonable_encoder(
        value,
    ...<4 lines>...
        sqlalchemy_safe=sqlalchemy_safe,
    )
  File "/Users/quick/Desktop/bill_generator-main/backend/venv/lib/python3.13/site-packages/fastapi/encoders.py", line 330, in jsonable_encoder
    raise ValueError(errors) from e
ValueError: [TypeError("'ObjectId' object is not iterable"), TypeError('vars() argument must have __dict__ attribute')]
INFO:     127.0.0.1:63345 - "POST /api/business/profile HTTP/1.1" 200 OK
INFO:     127.0.0.1:63359 - "GET /api/business/profile HTTP/1.1" 404 Not Found
INFO:     127.0.0.1:63359 - "GET /api/business/profile HTTP/1.1" 404 Not Found
INFO:     127.0.0.1:63529 - "GET /api/business/profile HTTP/1.1" 404 Not Found
INFO:     127.0.0.1:63529 - "GET /api/business/profile HTTP/1.1" 404 Not Found
INFO:     127.0.0.1:63529 - "GET /api/business/profile HTTP/1.1" 404 Not Found
INFO:     127.0.0.1:63529 - "GET /api/business/profile HTTP/1.1" 404 Not Found
INFO:     127.0.0.1:63529 - "GET /api/business/profile HTTP/1.1" 404 Not Found
INFO:     127.0.0.1:63529 - "GET /api/business/profile HTTP/1.1" 404 Not Found
INFO:     127.0.0.1:63529 - "OPTIONS /api/business/templates HTTP/1.1" 200 OK
INFO:     127.0.0.1:63540 - "OPTIONS /api/business/templates HTTP/1.1" 200 OK
INFO:     127.0.0.1:63529 - "GET /api/business/templates HTTP/1.1" 404 Not Found
INFO:     127.0.0.1:63529 - "GET /api/business/templates HTTP/1.1" 404 Not Found
INFO:     127.0.0.1:63529 - "GET /api/business/profile HTTP/1.1" 404 Not Found
INFO:     127.0.0.1:63529 - "GET /api/business/profile HTTP/1.1" 404 Not Found
INFO:     127.0.0.1:63529 - "GET /api/business/templates HTTP/1.1" 404 Not Found
INFO:     127.0.0.1:63529 - "GET /api/business/templates HTTP/1.1" 404 Not Found
INFO:     127.0.0.1:63529 - "OPTIONS /api/customers HTTP/1.1" 200 OK
INFO:     127.0.0.1:63540 - "OPTIONS /api/customers HTTP/1.1" 200 OK
INFO:     127.0.0.1:63542 - "GET /api/customers HTTP/1.1" 200 OK
INFO:     127.0.0.1:63542 - "GET /api/customers HTTP/1.1" 200 OK
INFO:     127.0.0.1:63542 - "GET /api/business/profile HTTP/1.1" 404 Not Found
INFO:     127.0.0.1:63542 - "GET /api/business/profile HTTP/1.1" 404 Not Found
INFO:     127.0.0.1:63542 - "OPTIONS /api/invoices HTTP/1.1" 200 OK
INFO:     127.0.0.1:63540 - "OPTIONS /api/invoices HTTP/1.1" 200 OK
INFO:     127.0.0.1:63529 - "GET /api/invoices HTTP/1.1" 200 OK
INFO:     127.0.0.1:63540 - "GET /api/invoices HTTP/1.1" 200 OK
INFO:     127.0.0.1:63540 - "GET /api/customers HTTP/1.1" 200 OK
INFO:     127.0.0.1:63540 - "GET /api/customers HTTP/1.1" 200 OK
INFO:     127.0.0.1:63540 - "GET /api/invoices HTTP/1.1" 200 OK
INFO:     127.0.0.1:63529 - "GET /api/invoices HTTP/1.1" 200 OK
INFO:     127.0.0.1:63529 - "GET /api/business/templates HTTP/1.1" 404 Not Found
INFO:     127.0.0.1:63529 - "GET /api/business/templates HTTP/1.1" 404 Not Found
INFO:     127.0.0.1:63529 - "GET /api/customers HTTP/1.1" 200 OK
INFO:     127.0.0.1:63529 - "GET /api/customers HTTP/1.1" 200 OK
INFO:     127.0.0.1:63529 - "GET /api/business/profile HTTP/1.1" 404 Not Found
INFO:     127.0.0.1:63529 - "GET /api/business/profile HTTP/1.1" 404 Not Found
INFO:     127.0.0.1:63529 - "GET /api/customers HTTP/1.1" 200 OK
INFO:     127.0.0.1:63529 - "GET /api/customers HTTP/1.1" 200 OK
INFO:     127.0.0.1:63529 - "OPTIONS /api/ HTTP/1.1" 200 OK
INFO:     127.0.0.1:63540 - "OPTIONS /api/ HTTP/1.1" 200 OK
INFO:     127.0.0.1:63542 - "GET /api/ HTTP/1.1" 200 OK
INFO:     127.0.0.1:63542 - "GET /api/ HTTP/1.1" 200 OK
INFO:     127.0.0.1:63542 - "GET /api/ HTTP/1.1" 200 OK
INFO:     127.0.0.1:63540 - "GET /api/ HTTP/1.1" 200 OK
INFO:     127.0.0.1:63540 - "GET /api/business/profile HTTP/1.1" 404 Not Found
INFO:     127.0.0.1:63540 - "GET /api/business/templates HTTP/1.1" 404 Not Found
INFO:     127.0.0.1:63540 - "GET /api/business/templates HTTP/1.1" 404 Not Found
INFO:     127.0.0.1:63564 - "GET /api/business/profile HTTP/1.1" 404 Not Found
INFO:     127.0.0.1:63564 - "GET /api/business/profile HTTP/1.1" 404 Not Found
INFO:     127.0.0.1:63585 - "POST /api/business/profile HTTP/1.1" 200 OK
INFO:     127.0.0.1:63585 - "POST /api/business/profile HTTP/1.1" 200 OK
INFO:     127.0.0.1:63585 - "POST /api/business/generate-template HTTP/1.1" 500 Internal Server Error
ERROR:    Exception in ASGI application
Traceback (most recent call last):
  File "/Users/quick/Desktop/bill_generator-main/backend/venv/lib/python3.13/site-packages/fastapi/encoders.py", line 322, in jsonable_encoder
    data = dict(obj)
TypeError: 'ObjectId' object is not iterable

During handling of the above exception, another exception occurred:

Traceback (most recent call last):
  File "/Users/quick/Desktop/bill_generator-main/backend/venv/lib/python3.13/site-packages/fastapi/encoders.py", line 327, in jsonable_encoder
    data = vars(obj)
TypeError: vars() argument must have __dict__ attribute

The above exception was the direct cause of the following exception:

Traceback (most recent call last):
  File "/Users/quick/Desktop/bill_generator-main/backend/venv/lib/python3.13/site-packages/uvicorn/protocols/http/h11_impl.py", line 408, in run_asgi
    result = await app(  # type: ignore[func-returns-value]
             ^^^^^^^^^^^^^^^^^^^^^^^^^^^^^^^^^^^^^^^^^^^^^^
        self.scope, self.receive, self.send
        ^^^^^^^^^^^^^^^^^^^^^^^^^^^^^^^^^^^
    )
    ^
  File "/Users/quick/Desktop/bill_generator-main/backend/venv/lib/python3.13/site-packages/uvicorn/middleware/proxy_headers.py", line 84, in __call__
    return await self.app(scope, receive, send)
           ^^^^^^^^^^^^^^^^^^^^^^^^^^^^^^^^^^^^
  File "/Users/quick/Desktop/bill_generator-main/backend/venv/lib/python3.13/site-packages/fastapi/applications.py", line 1054, in __call__
    await super().__call__(scope, receive, send)
  File "/Users/quick/Desktop/bill_generator-main/backend/venv/lib/python3.13/site-packages/starlette/applications.py", line 123, in __call__
    await self.middleware_stack(scope, receive, send)
  File "/Users/quick/Desktop/bill_generator-main/backend/venv/lib/python3.13/site-packages/starlette/middleware/errors.py", line 186, in __call__
    raise exc
  File "/Users/quick/Desktop/bill_generator-main/backend/venv/lib/python3.13/site-packages/starlette/middleware/errors.py", line 164, in __call__
    await self.app(scope, receive, _send)
  File "/Users/quick/Desktop/bill_generator-main/backend/venv/lib/python3.13/site-packages/starlette/middleware/cors.py", line 93, in __call__
    await self.simple_response(scope, receive, send, request_headers=headers)
  File "/Users/quick/Desktop/bill_generator-main/backend/venv/lib/python3.13/site-packages/starlette/middleware/cors.py", line 148, in simple_response
    await self.app(scope, receive, send)
  File "/Users/quick/Desktop/bill_generator-main/backend/venv/lib/python3.13/site-packages/starlette/middleware/exceptions.py", line 65, in __call__
    await wrap_app_handling_exceptions(self.app, conn)(scope, receive, send)
  File "/Users/quick/Desktop/bill_generator-main/backend/venv/lib/python3.13/site-packages/starlette/_exception_handler.py", line 64, in wrapped_app
    raise exc
  File "/Users/quick/Desktop/bill_generator-main/backend/venv/lib/python3.13/site-packages/starlette/_exception_handler.py", line 53, in wrapped_app
    await app(scope, receive, sender)
  File "/Users/quick/Desktop/bill_generator-main/backend/venv/lib/python3.13/site-packages/starlette/routing.py", line 756, in __call__
    await self.middleware_stack(scope, receive, send)
  File "/Users/quick/Desktop/bill_generator-main/backend/venv/lib/python3.13/site-packages/starlette/routing.py", line 776, in app
    await route.handle(scope, receive, send)
  File "/Users/quick/Desktop/bill_generator-main/backend/venv/lib/python3.13/site-packages/starlette/routing.py", line 297, in handle
    await self.app(scope, receive, send)
  File "/Users/quick/Desktop/bill_generator-main/backend/venv/lib/python3.13/site-packages/starlette/routing.py", line 77, in app
    await wrap_app_handling_exceptions(app, request)(scope, receive, send)
  File "/Users/quick/Desktop/bill_generator-main/backend/venv/lib/python3.13/site-packages/starlette/_exception_handler.py", line 64, in wrapped_app
    raise exc
  File "/Users/quick/Desktop/bill_generator-main/backend/venv/lib/python3.13/site-packages/starlette/_exception_handler.py", line 53, in wrapped_app
    await app(scope, receive, sender)
  File "/Users/quick/Desktop/bill_generator-main/backend/venv/lib/python3.13/site-packages/starlette/routing.py", line 72, in app
    response = await func(request)
               ^^^^^^^^^^^^^^^^^^^
  File "/Users/quick/Desktop/bill_generator-main/backend/venv/lib/python3.13/site-packages/fastapi/routing.py", line 296, in app
    content = await serialize_response(
              ^^^^^^^^^^^^^^^^^^^^^^^^^
    ...<9 lines>...
    )
    ^
  File "/Users/quick/Desktop/bill_generator-main/backend/venv/lib/python3.13/site-packages/fastapi/routing.py", line 180, in serialize_response
    return jsonable_encoder(response_content)
  File "/Users/quick/Desktop/bill_generator-main/backend/venv/lib/python3.13/site-packages/fastapi/encoders.py", line 287, in jsonable_encoder
    encoded_value = jsonable_encoder(
        value,
    ...<4 lines>...
        sqlalchemy_safe=sqlalchemy_safe,
    )
  File "/Users/quick/Desktop/bill_generator-main/backend/venv/lib/python3.13/site-packages/fastapi/encoders.py", line 287, in jsonable_encoder
    encoded_value = jsonable_encoder(
        value,
    ...<4 lines>...
        sqlalchemy_safe=sqlalchemy_safe,
    )
  File "/Users/quick/Desktop/bill_generator-main/backend/venv/lib/python3.13/site-packages/fastapi/encoders.py", line 330, in jsonable_encoder
    raise ValueError(errors) from e
ValueError: [TypeError("'ObjectId' object is not iterable"), TypeError('vars() argument must have __dict__ attribute')]
INFO:     127.0.0.1:63589 - "POST /api/business/profile HTTP/1.1" 200 OK
INFO:     127.0.0.1:63589 - "POST /api/business/generate-template HTTP/1.1" 500 Internal Server Error
ERROR:    Exception in ASGI application
Traceback (most recent call last):
  File "/Users/quick/Desktop/bill_generator-main/backend/venv/lib/python3.13/site-packages/fastapi/encoders.py", line 322, in jsonable_encoder
    data = dict(obj)
TypeError: 'ObjectId' object is not iterable

During handling of the above exception, another exception occurred:

Traceback (most recent call last):
  File "/Users/quick/Desktop/bill_generator-main/backend/venv/lib/python3.13/site-packages/fastapi/encoders.py", line 327, in jsonable_encoder
    data = vars(obj)
TypeError: vars() argument must have __dict__ attribute

The above exception was the direct cause of the following exception:

Traceback (most recent call last):
  File "/Users/quick/Desktop/bill_generator-main/backend/venv/lib/python3.13/site-packages/uvicorn/protocols/http/h11_impl.py", line 408, in run_asgi
    result = await app(  # type: ignore[func-returns-value]
             ^^^^^^^^^^^^^^^^^^^^^^^^^^^^^^^^^^^^^^^^^^^^^^
        self.scope, self.receive, self.send
        ^^^^^^^^^^^^^^^^^^^^^^^^^^^^^^^^^^^
    )
    ^
  File "/Users/quick/Desktop/bill_generator-main/backend/venv/lib/python3.13/site-packages/uvicorn/middleware/proxy_headers.py", line 84, in __call__
    return await self.app(scope, receive, send)
           ^^^^^^^^^^^^^^^^^^^^^^^^^^^^^^^^^^^^
  File "/Users/quick/Desktop/bill_generator-main/backend/venv/lib/python3.13/site-packages/fastapi/applications.py", line 1054, in __call__
    await super().__call__(scope, receive, send)
  File "/Users/quick/Desktop/bill_generator-main/backend/venv/lib/python3.13/site-packages/starlette/applications.py", line 123, in __call__
    await self.middleware_stack(scope, receive, send)
  File "/Users/quick/Desktop/bill_generator-main/backend/venv/lib/python3.13/site-packages/starlette/middleware/errors.py", line 186, in __call__
    raise exc
  File "/Users/quick/Desktop/bill_generator-main/backend/venv/lib/python3.13/site-packages/starlette/middleware/errors.py", line 164, in __call__
    await self.app(scope, receive, _send)
  File "/Users/quick/Desktop/bill_generator-main/backend/venv/lib/python3.13/site-packages/starlette/middleware/cors.py", line 93, in __call__
    await self.simple_response(scope, receive, send, request_headers=headers)
  File "/Users/quick/Desktop/bill_generator-main/backend/venv/lib/python3.13/site-packages/starlette/middleware/cors.py", line 148, in simple_response
    await self.app(scope, receive, send)
  File "/Users/quick/Desktop/bill_generator-main/backend/venv/lib/python3.13/site-packages/starlette/middleware/exceptions.py", line 65, in __call__
    await wrap_app_handling_exceptions(self.app, conn)(scope, receive, send)
  File "/Users/quick/Desktop/bill_generator-main/backend/venv/lib/python3.13/site-packages/starlette/_exception_handler.py", line 64, in wrapped_app
    raise exc
  File "/Users/quick/Desktop/bill_generator-main/backend/venv/lib/python3.13/site-packages/starlette/_exception_handler.py", line 53, in wrapped_app
    await app(scope, receive, sender)
  File "/Users/quick/Desktop/bill_generator-main/backend/venv/lib/python3.13/site-packages/starlette/routing.py", line 756, in __call__
    await self.middleware_stack(scope, receive, send)
  File "/Users/quick/Desktop/bill_generator-main/backend/venv/lib/python3.13/site-packages/starlette/routing.py", line 776, in app
    await route.handle(scope, receive, send)
  File "/Users/quick/Desktop/bill_generator-main/backend/venv/lib/python3.13/site-packages/starlette/routing.py", line 297, in handle
    await self.app(scope, receive, send)
  File "/Users/quick/Desktop/bill_generator-main/backend/venv/lib/python3.13/site-packages/starlette/routing.py", line 77, in app
    await wrap_app_handling_exceptions(app, request)(scope, receive, send)
  File "/Users/quick/Desktop/bill_generator-main/backend/venv/lib/python3.13/site-packages/starlette/_exception_handler.py", line 64, in wrapped_app
    raise exc
  File "/Users/quick/Desktop/bill_generator-main/backend/venv/lib/python3.13/site-packages/starlette/_exception_handler.py", line 53, in wrapped_app
    await app(scope, receive, sender)
  File "/Users/quick/Desktop/bill_generator-main/backend/venv/lib/python3.13/site-packages/starlette/routing.py", line 72, in app
    response = await func(request)
               ^^^^^^^^^^^^^^^^^^^
  File "/Users/quick/Desktop/bill_generator-main/backend/venv/lib/python3.13/site-packages/fastapi/routing.py", line 296, in app
    content = await serialize_response(
              ^^^^^^^^^^^^^^^^^^^^^^^^^
    ...<9 lines>...
    )
    ^
  File "/Users/quick/Desktop/bill_generator-main/backend/venv/lib/python3.13/site-packages/fastapi/routing.py", line 180, in serialize_response
    return jsonable_encoder(response_content)
  File "/Users/quick/Desktop/bill_generator-main/backend/venv/lib/python3.13/site-packages/fastapi/encoders.py", line 287, in jsonable_encoder
    encoded_value = jsonable_encoder(
        value,
    ...<4 lines>...
        sqlalchemy_safe=sqlalchemy_safe,
    )
  File "/Users/quick/Desktop/bill_generator-main/backend/venv/lib/python3.13/site-packages/fastapi/encoders.py", line 287, in jsonable_encoder
    encoded_value = jsonable_encoder(
        value,
    ...<4 lines>...
        sqlalchemy_safe=sqlalchemy_safe,
    )
  File "/Users/quick/Desktop/bill_generator-main/backend/venv/lib/python3.13/site-packages/fastapi/encoders.py", line 330, in jsonable_encoder
    raise ValueError(errors) from e
ValueError: [TypeError("'ObjectId' object is not iterable"), TypeError('vars() argument must have __dict__ attribute')]
INFO:     127.0.0.1:63613 - "OPTIONS /api/business/profile HTTP/1.1" 200 OK
INFO:     127.0.0.1:63613 - "POST /api/business/profile HTTP/1.1" 200 OK
INFO:     127.0.0.1:63613 - "GET /api/business/templates HTTP/1.1" 404 Not Found
INFO:     127.0.0.1:63613 - "GET /api/business/templates HTTP/1.1" 404 Not Found
INFO:     127.0.0.1:63615 - "GET /api/business/profile HTTP/1.1" 404 Not Found
INFO:     127.0.0.1:63615 - "GET /api/business/profile HTTP/1.1" 404 Not Found
INFO:     127.0.0.1:63615 - "GET /api/business/templates HTTP/1.1" 404 Not Found
INFO:     127.0.0.1:63615 - "GET /api/business/templates HTTP/1.1" 404 Not Found
INFO:     127.0.0.1:63615 - "GET /api/business/profile HTTP/1.1" 404 Not Found
INFO:     127.0.0.1:63615 - "GET /api/business/profile HTTP/1.1" 404 Not Found
INFO:     127.0.0.1:63637 - "POST /api/business/profile HTTP/1.1" 200 OK
INFO:     127.0.0.1:63637 - "POST /api/business/profile HTTP/1.1" 200 OK
INFO:     127.0.0.1:63637 - "OPTIONS /api/business/generate-template HTTP/1.1" 200 OK
INFO:     127.0.0.1:63637 - "POST /api/business/generate-template HTTP/1.1" 500 Internal Server Error
ERROR:    Exception in ASGI application
Traceback (most recent call last):
  File "/Users/quick/Desktop/bill_generator-main/backend/venv/lib/python3.13/site-packages/fastapi/encoders.py", line 322, in jsonable_encoder
    data = dict(obj)
TypeError: 'ObjectId' object is not iterable

During handling of the above exception, another exception occurred:

Traceback (most recent call last):
  File "/Users/quick/Desktop/bill_generator-main/backend/venv/lib/python3.13/site-packages/fastapi/encoders.py", line 327, in jsonable_encoder
    data = vars(obj)
TypeError: vars() argument must have __dict__ attribute

The above exception was the direct cause of the following exception:

Traceback (most recent call last):
  File "/Users/quick/Desktop/bill_generator-main/backend/venv/lib/python3.13/site-packages/uvicorn/protocols/http/h11_impl.py", line 408, in run_asgi
    result = await app(  # type: ignore[func-returns-value]
             ^^^^^^^^^^^^^^^^^^^^^^^^^^^^^^^^^^^^^^^^^^^^^^
        self.scope, self.receive, self.send
        ^^^^^^^^^^^^^^^^^^^^^^^^^^^^^^^^^^^
    )
    ^
  File "/Users/quick/Desktop/bill_generator-main/backend/venv/lib/python3.13/site-packages/uvicorn/middleware/proxy_headers.py", line 84, in __call__
    return await self.app(scope, receive, send)
           ^^^^^^^^^^^^^^^^^^^^^^^^^^^^^^^^^^^^
  File "/Users/quick/Desktop/bill_generator-main/backend/venv/lib/python3.13/site-packages/fastapi/applications.py", line 1054, in __call__
    await super().__call__(scope, receive, send)
  File "/Users/quick/Desktop/bill_generator-main/backend/venv/lib/python3.13/site-packages/starlette/applications.py", line 123, in __call__
    await self.middleware_stack(scope, receive, send)
  File "/Users/quick/Desktop/bill_generator-main/backend/venv/lib/python3.13/site-packages/starlette/middleware/errors.py", line 186, in __call__
    raise exc
  File "/Users/quick/Desktop/bill_generator-main/backend/venv/lib/python3.13/site-packages/starlette/middleware/errors.py", line 164, in __call__
    await self.app(scope, receive, _send)
  File "/Users/quick/Desktop/bill_generator-main/backend/venv/lib/python3.13/site-packages/starlette/middleware/cors.py", line 93, in __call__
    await self.simple_response(scope, receive, send, request_headers=headers)
  File "/Users/quick/Desktop/bill_generator-main/backend/venv/lib/python3.13/site-packages/starlette/middleware/cors.py", line 148, in simple_response
    await self.app(scope, receive, send)
  File "/Users/quick/Desktop/bill_generator-main/backend/venv/lib/python3.13/site-packages/starlette/middleware/exceptions.py", line 65, in __call__
    await wrap_app_handling_exceptions(self.app, conn)(scope, receive, send)
  File "/Users/quick/Desktop/bill_generator-main/backend/venv/lib/python3.13/site-packages/starlette/_exception_handler.py", line 64, in wrapped_app
    raise exc
  File "/Users/quick/Desktop/bill_generator-main/backend/venv/lib/python3.13/site-packages/starlette/_exception_handler.py", line 53, in wrapped_app
    await app(scope, receive, sender)
  File "/Users/quick/Desktop/bill_generator-main/backend/venv/lib/python3.13/site-packages/starlette/routing.py", line 756, in __call__
    await self.middleware_stack(scope, receive, send)
  File "/Users/quick/Desktop/bill_generator-main/backend/venv/lib/python3.13/site-packages/starlette/routing.py", line 776, in app
    await route.handle(scope, receive, send)
  File "/Users/quick/Desktop/bill_generator-main/backend/venv/lib/python3.13/site-packages/starlette/routing.py", line 297, in handle
    await self.app(scope, receive, send)
  File "/Users/quick/Desktop/bill_generator-main/backend/venv/lib/python3.13/site-packages/starlette/routing.py", line 77, in app
    await wrap_app_handling_exceptions(app, request)(scope, receive, send)
  File "/Users/quick/Desktop/bill_generator-main/backend/venv/lib/python3.13/site-packages/starlette/_exception_handler.py", line 64, in wrapped_app
    raise exc
  File "/Users/quick/Desktop/bill_generator-main/backend/venv/lib/python3.13/site-packages/starlette/_exception_handler.py", line 53, in wrapped_app
    await app(scope, receive, sender)
  File "/Users/quick/Desktop/bill_generator-main/backend/venv/lib/python3.13/site-packages/starlette/routing.py", line 72, in app
    response = await func(request)
               ^^^^^^^^^^^^^^^^^^^
  File "/Users/quick/Desktop/bill_generator-main/backend/venv/lib/python3.13/site-packages/fastapi/routing.py", line 296, in app
    content = await serialize_response(
              ^^^^^^^^^^^^^^^^^^^^^^^^^
    ...<9 lines>...
    )
    ^
  File "/Users/quick/Desktop/bill_generator-main/backend/venv/lib/python3.13/site-packages/fastapi/routing.py", line 180, in serialize_response
    return jsonable_encoder(response_content)
  File "/Users/quick/Desktop/bill_generator-main/backend/venv/lib/python3.13/site-packages/fastapi/encoders.py", line 287, in jsonable_encoder
    encoded_value = jsonable_encoder(
        value,
    ...<4 lines>...
        sqlalchemy_safe=sqlalchemy_safe,
    )
  File "/Users/quick/Desktop/bill_generator-main/backend/venv/lib/python3.13/site-packages/fastapi/encoders.py", line 287, in jsonable_encoder
    encoded_value = jsonable_encoder(
        value,
    ...<4 lines>...
        sqlalchemy_safe=sqlalchemy_safe,
    )
  File "/Users/quick/Desktop/bill_generator-main/backend/venv/lib/python3.13/site-packages/fastapi/encoders.py", line 330, in jsonable_encoder
    raise ValueError(errors) from e
ValueError: [TypeError("'ObjectId' object is not iterable"), TypeError('vars() argument must have __dict__ attribute')]
INFO:     127.0.0.1:63639 - "POST /api/business/profile HTTP/1.1" 200 OK
INFO:     127.0.0.1:63639 - "POST /api/business/generate-template HTTP/1.1" 500 Internal Server Error
ERROR:    Exception in ASGI application
Traceback (most recent call last):
  File "/Users/quick/Desktop/bill_generator-main/backend/venv/lib/python3.13/site-packages/fastapi/encoders.py", line 322, in jsonable_encoder
    data = dict(obj)
TypeError: 'ObjectId' object is not iterable

During handling of the above exception, another exception occurred:

Traceback (most recent call last):
  File "/Users/quick/Desktop/bill_generator-main/backend/venv/lib/python3.13/site-packages/fastapi/encoders.py", line 327, in jsonable_encoder
    data = vars(obj)
TypeError: vars() argument must have __dict__ attribute

The above exception was the direct cause of the following exception:

Traceback (most recent call last):
  File "/Users/quick/Desktop/bill_generator-main/backend/venv/lib/python3.13/site-packages/uvicorn/protocols/http/h11_impl.py", line 408, in run_asgi
    result = await app(  # type: ignore[func-returns-value]
             ^^^^^^^^^^^^^^^^^^^^^^^^^^^^^^^^^^^^^^^^^^^^^^
        self.scope, self.receive, self.send
        ^^^^^^^^^^^^^^^^^^^^^^^^^^^^^^^^^^^
    )
    ^
  File "/Users/quick/Desktop/bill_generator-main/backend/venv/lib/python3.13/site-packages/uvicorn/middleware/proxy_headers.py", line 84, in __call__
    return await self.app(scope, receive, send)
           ^^^^^^^^^^^^^^^^^^^^^^^^^^^^^^^^^^^^
  File "/Users/quick/Desktop/bill_generator-main/backend/venv/lib/python3.13/site-packages/fastapi/applications.py", line 1054, in __call__
    await super().__call__(scope, receive, send)
  File "/Users/quick/Desktop/bill_generator-main/backend/venv/lib/python3.13/site-packages/starlette/applications.py", line 123, in __call__
    await self.middleware_stack(scope, receive, send)
  File "/Users/quick/Desktop/bill_generator-main/backend/venv/lib/python3.13/site-packages/starlette/middleware/errors.py", line 186, in __call__
    raise exc
  File "/Users/quick/Desktop/bill_generator-main/backend/venv/lib/python3.13/site-packages/starlette/middleware/errors.py", line 164, in __call__
    await self.app(scope, receive, _send)
  File "/Users/quick/Desktop/bill_generator-main/backend/venv/lib/python3.13/site-packages/starlette/middleware/cors.py", line 93, in __call__
    await self.simple_response(scope, receive, send, request_headers=headers)
  File "/Users/quick/Desktop/bill_generator-main/backend/venv/lib/python3.13/site-packages/starlette/middleware/cors.py", line 148, in simple_response
    await self.app(scope, receive, send)
  File "/Users/quick/Desktop/bill_generator-main/backend/venv/lib/python3.13/site-packages/starlette/middleware/exceptions.py", line 65, in __call__
    await wrap_app_handling_exceptions(self.app, conn)(scope, receive, send)
  File "/Users/quick/Desktop/bill_generator-main/backend/venv/lib/python3.13/site-packages/starlette/_exception_handler.py", line 64, in wrapped_app
    raise exc
  File "/Users/quick/Desktop/bill_generator-main/backend/venv/lib/python3.13/site-packages/starlette/_exception_handler.py", line 53, in wrapped_app
    await app(scope, receive, sender)
  File "/Users/quick/Desktop/bill_generator-main/backend/venv/lib/python3.13/site-packages/starlette/routing.py", line 756, in __call__
    await self.middleware_stack(scope, receive, send)
  File "/Users/quick/Desktop/bill_generator-main/backend/venv/lib/python3.13/site-packages/starlette/routing.py", line 776, in app
    await route.handle(scope, receive, send)
  File "/Users/quick/Desktop/bill_generator-main/backend/venv/lib/python3.13/site-packages/starlette/routing.py", line 297, in handle
    await self.app(scope, receive, send)
  File "/Users/quick/Desktop/bill_generator-main/backend/venv/lib/python3.13/site-packages/starlette/routing.py", line 77, in app
    await wrap_app_handling_exceptions(app, request)(scope, receive, send)
  File "/Users/quick/Desktop/bill_generator-main/backend/venv/lib/python3.13/site-packages/starlette/_exception_handler.py", line 64, in wrapped_app
    raise exc
  File "/Users/quick/Desktop/bill_generator-main/backend/venv/lib/python3.13/site-packages/starlette/_exception_handler.py", line 53, in wrapped_app
    await app(scope, receive, sender)
  File "/Users/quick/Desktop/bill_generator-main/backend/venv/lib/python3.13/site-packages/starlette/routing.py", line 72, in app
    response = await func(request)
               ^^^^^^^^^^^^^^^^^^^
  File "/Users/quick/Desktop/bill_generator-main/backend/venv/lib/python3.13/site-packages/fastapi/routing.py", line 296, in app
    content = await serialize_response(
              ^^^^^^^^^^^^^^^^^^^^^^^^^
    ...<9 lines>...
    )
    ^
  File "/Users/quick/Desktop/bill_generator-main/backend/venv/lib/python3.13/site-packages/fastapi/routing.py", line 180, in serialize_response
    return jsonable_encoder(response_content)
  File "/Users/quick/Desktop/bill_generator-main/backend/venv/lib/python3.13/site-packages/fastapi/encoders.py", line 287, in jsonable_encoder
    encoded_value = jsonable_encoder(
        value,
    ...<4 lines>...
        sqlalchemy_safe=sqlalchemy_safe,
    )
  File "/Users/quick/Desktop/bill_generator-main/backend/venv/lib/python3.13/site-packages/fastapi/encoders.py", line 287, in jsonable_encoder
    encoded_value = jsonable_encoder(
        value,
    ...<4 lines>...
        sqlalchemy_safe=sqlalchemy_safe,
    )
  File "/Users/quick/Desktop/bill_generator-main/backend/venv/lib/python3.13/site-packages/fastapi/encoders.py", line 330, in jsonable_encoder
    raise ValueError(errors) from e
ValueError: [TypeError("'ObjectId' object is not iterable"), TypeError('vars() argument must have __dict__ attribute')]
INFO:     127.0.0.1:63643 - "POST /api/business/profile HTTP/1.1" 200 OK
INFO:     127.0.0.1:63643 - "POST /api/business/generate-template HTTP/1.1" 500 Internal Server Error
ERROR:    Exception in ASGI application
Traceback (most recent call last):
  File "/Users/quick/Desktop/bill_generator-main/backend/venv/lib/python3.13/site-packages/fastapi/encoders.py", line 322, in jsonable_encoder
    data = dict(obj)
TypeError: 'ObjectId' object is not iterable

During handling of the above exception, another exception occurred:

Traceback (most recent call last):
  File "/Users/quick/Desktop/bill_generator-main/backend/venv/lib/python3.13/site-packages/fastapi/encoders.py", line 327, in jsonable_encoder
    data = vars(obj)
TypeError: vars() argument must have __dict__ attribute

The above exception was the direct cause of the following exception:

Traceback (most recent call last):
  File "/Users/quick/Desktop/bill_generator-main/backend/venv/lib/python3.13/site-packages/uvicorn/protocols/http/h11_impl.py", line 408, in run_asgi
    result = await app(  # type: ignore[func-returns-value]
             ^^^^^^^^^^^^^^^^^^^^^^^^^^^^^^^^^^^^^^^^^^^^^^
        self.scope, self.receive, self.send
        ^^^^^^^^^^^^^^^^^^^^^^^^^^^^^^^^^^^
    )
    ^
  File "/Users/quick/Desktop/bill_generator-main/backend/venv/lib/python3.13/site-packages/uvicorn/middleware/proxy_headers.py", line 84, in __call__
    return await self.app(scope, receive, send)
           ^^^^^^^^^^^^^^^^^^^^^^^^^^^^^^^^^^^^
  File "/Users/quick/Desktop/bill_generator-main/backend/venv/lib/python3.13/site-packages/fastapi/applications.py", line 1054, in __call__
    await super().__call__(scope, receive, send)
  File "/Users/quick/Desktop/bill_generator-main/backend/venv/lib/python3.13/site-packages/starlette/applications.py", line 123, in __call__
    await self.middleware_stack(scope, receive, send)
  File "/Users/quick/Desktop/bill_generator-main/backend/venv/lib/python3.13/site-packages/starlette/middleware/errors.py", line 186, in __call__
    raise exc
  File "/Users/quick/Desktop/bill_generator-main/backend/venv/lib/python3.13/site-packages/starlette/middleware/errors.py", line 164, in __call__
    await self.app(scope, receive, _send)
  File "/Users/quick/Desktop/bill_generator-main/backend/venv/lib/python3.13/site-packages/starlette/middleware/cors.py", line 93, in __call__
    await self.simple_response(scope, receive, send, request_headers=headers)
  File "/Users/quick/Desktop/bill_generator-main/backend/venv/lib/python3.13/site-packages/starlette/middleware/cors.py", line 148, in simple_response
    await self.app(scope, receive, send)
  File "/Users/quick/Desktop/bill_generator-main/backend/venv/lib/python3.13/site-packages/starlette/middleware/exceptions.py", line 65, in __call__
    await wrap_app_handling_exceptions(self.app, conn)(scope, receive, send)
  File "/Users/quick/Desktop/bill_generator-main/backend/venv/lib/python3.13/site-packages/starlette/_exception_handler.py", line 64, in wrapped_app
    raise exc
  File "/Users/quick/Desktop/bill_generator-main/backend/venv/lib/python3.13/site-packages/starlette/_exception_handler.py", line 53, in wrapped_app
    await app(scope, receive, sender)
  File "/Users/quick/Desktop/bill_generator-main/backend/venv/lib/python3.13/site-packages/starlette/routing.py", line 756, in __call__
    await self.middleware_stack(scope, receive, send)
  File "/Users/quick/Desktop/bill_generator-main/backend/venv/lib/python3.13/site-packages/starlette/routing.py", line 776, in app
    await route.handle(scope, receive, send)
  File "/Users/quick/Desktop/bill_generator-main/backend/venv/lib/python3.13/site-packages/starlette/routing.py", line 297, in handle
    await self.app(scope, receive, send)
  File "/Users/quick/Desktop/bill_generator-main/backend/venv/lib/python3.13/site-packages/starlette/routing.py", line 77, in app
    await wrap_app_handling_exceptions(app, request)(scope, receive, send)
  File "/Users/quick/Desktop/bill_generator-main/backend/venv/lib/python3.13/site-packages/starlette/_exception_handler.py", line 64, in wrapped_app
    raise exc
  File "/Users/quick/Desktop/bill_generator-main/backend/venv/lib/python3.13/site-packages/starlette/_exception_handler.py", line 53, in wrapped_app
    await app(scope, receive, sender)
  File "/Users/quick/Desktop/bill_generator-main/backend/venv/lib/python3.13/site-packages/starlette/routing.py", line 72, in app
    response = await func(request)
               ^^^^^^^^^^^^^^^^^^^
  File "/Users/quick/Desktop/bill_generator-main/backend/venv/lib/python3.13/site-packages/fastapi/routing.py", line 296, in app
    content = await serialize_response(
              ^^^^^^^^^^^^^^^^^^^^^^^^^
    ...<9 lines>...
    )
    ^
  File "/Users/quick/Desktop/bill_generator-main/backend/venv/lib/python3.13/site-packages/fastapi/routing.py", line 180, in serialize_response
    return jsonable_encoder(response_content)
  File "/Users/quick/Desktop/bill_generator-main/backend/venv/lib/python3.13/site-packages/fastapi/encoders.py", line 287, in jsonable_encoder
    encoded_value = jsonable_encoder(
        value,
    ...<4 lines>...
        sqlalchemy_safe=sqlalchemy_safe,
    )
  File "/Users/quick/Desktop/bill_generator-main/backend/venv/lib/python3.13/site-packages/fastapi/encoders.py", line 287, in jsonable_encoder
    encoded_value = jsonable_encoder(
        value,
    ...<4 lines>...
        sqlalchemy_safe=sqlalchemy_safe,
    )
  File "/Users/quick/Desktop/bill_generator-main/backend/venv/lib/python3.13/site-packages/fastapi/encoders.py", line 330, in jsonable_encoder
    raise ValueError(errors) from e
ValueError: [TypeError("'ObjectId' object is not iterable"), TypeError('vars() argument must have __dict__ attribute')]
INFO:     127.0.0.1:63716 - "GET /api/ HTTP/1.1" 200 OK
INFO:     127.0.0.1:63722 - "POST /api/business/generate-template HTTP/1.1" 401 Unauthorized
INFO:     127.0.0.1:63803 - "GET /api/business/profile HTTP/1.1" 404 Not Found
INFO:     127.0.0.1:63803 - "GET /api/business/profile HTTP/1.1" 404 Not Found
INFO:     127.0.0.1:63803 - "GET /api/business/profile HTTP/1.1" 404 Not Found
INFO:     127.0.0.1:63816 - "GET /api/ HTTP/1.1" 200 OK
INFO:     127.0.0.1:63816 - "GET /api/ HTTP/1.1" 200 OK
INFO:     127.0.0.1:63816 - "GET /api/business/profile HTTP/1.1" 404 Not Found
INFO:     127.0.0.1:63816 - "GET /api/customers HTTP/1.1" 200 OK
INFO:     127.0.0.1:63816 - "GET /api/customers HTTP/1.1" 200 OK
INFO:     127.0.0.1:63816 - "GET /api/business/profile HTTP/1.1" 404 Not Found
INFO:     127.0.0.1:63816 - "GET /api/business/profile HTTP/1.1" 404 Not Found
INFO:     127.0.0.1:63845 - "POST /api/business/profile HTTP/1.1" 200 OK
INFO:     127.0.0.1:63845 - "POST /api/business/profile HTTP/1.1" 200 OK
INFO:     127.0.0.1:63845 - "OPTIONS /api/business/generate-template HTTP/1.1" 200 OK
INFO:     127.0.0.1:63847 - "POST /api/business/generate-template HTTP/1.1" 500 Internal Server Error
ERROR:    Exception in ASGI application
Traceback (most recent call last):
  File "/Users/quick/Desktop/bill_generator-main/backend/venv/lib/python3.13/site-packages/fastapi/encoders.py", line 322, in jsonable_encoder
    data = dict(obj)
TypeError: 'ObjectId' object is not iterable

During handling of the above exception, another exception occurred:

Traceback (most recent call last):
  File "/Users/quick/Desktop/bill_generator-main/backend/venv/lib/python3.13/site-packages/fastapi/encoders.py", line 327, in jsonable_encoder
    data = vars(obj)
TypeError: vars() argument must have __dict__ attribute

The above exception was the direct cause of the following exception:

Traceback (most recent call last):
  File "/Users/quick/Desktop/bill_generator-main/backend/venv/lib/python3.13/site-packages/uvicorn/protocols/http/h11_impl.py", line 408, in run_asgi
    result = await app(  # type: ignore[func-returns-value]
             ^^^^^^^^^^^^^^^^^^^^^^^^^^^^^^^^^^^^^^^^^^^^^^
        self.scope, self.receive, self.send
        ^^^^^^^^^^^^^^^^^^^^^^^^^^^^^^^^^^^
    )
    ^
  File "/Users/quick/Desktop/bill_generator-main/backend/venv/lib/python3.13/site-packages/uvicorn/middleware/proxy_headers.py", line 84, in __call__
    return await self.app(scope, receive, send)
           ^^^^^^^^^^^^^^^^^^^^^^^^^^^^^^^^^^^^
  File "/Users/quick/Desktop/bill_generator-main/backend/venv/lib/python3.13/site-packages/fastapi/applications.py", line 1054, in __call__
    await super().__call__(scope, receive, send)
  File "/Users/quick/Desktop/bill_generator-main/backend/venv/lib/python3.13/site-packages/starlette/applications.py", line 123, in __call__
    await self.middleware_stack(scope, receive, send)
  File "/Users/quick/Desktop/bill_generator-main/backend/venv/lib/python3.13/site-packages/starlette/middleware/errors.py", line 186, in __call__
    raise exc
  File "/Users/quick/Desktop/bill_generator-main/backend/venv/lib/python3.13/site-packages/starlette/middleware/errors.py", line 164, in __call__
    await self.app(scope, receive, _send)
  File "/Users/quick/Desktop/bill_generator-main/backend/venv/lib/python3.13/site-packages/starlette/middleware/cors.py", line 93, in __call__
    await self.simple_response(scope, receive, send, request_headers=headers)
  File "/Users/quick/Desktop/bill_generator-main/backend/venv/lib/python3.13/site-packages/starlette/middleware/cors.py", line 148, in simple_response
    await self.app(scope, receive, send)
  File "/Users/quick/Desktop/bill_generator-main/backend/venv/lib/python3.13/site-packages/starlette/middleware/exceptions.py", line 65, in __call__
    await wrap_app_handling_exceptions(self.app, conn)(scope, receive, send)
  File "/Users/quick/Desktop/bill_generator-main/backend/venv/lib/python3.13/site-packages/starlette/_exception_handler.py", line 64, in wrapped_app
    raise exc
  File "/Users/quick/Desktop/bill_generator-main/backend/venv/lib/python3.13/site-packages/starlette/_exception_handler.py", line 53, in wrapped_app
    await app(scope, receive, sender)
  File "/Users/quick/Desktop/bill_generator-main/backend/venv/lib/python3.13/site-packages/starlette/routing.py", line 756, in __call__
    await self.middleware_stack(scope, receive, send)
  File "/Users/quick/Desktop/bill_generator-main/backend/venv/lib/python3.13/site-packages/starlette/routing.py", line 776, in app
    await route.handle(scope, receive, send)
  File "/Users/quick/Desktop/bill_generator-main/backend/venv/lib/python3.13/site-packages/starlette/routing.py", line 297, in handle
    await self.app(scope, receive, send)
  File "/Users/quick/Desktop/bill_generator-main/backend/venv/lib/python3.13/site-packages/starlette/routing.py", line 77, in app
    await wrap_app_handling_exceptions(app, request)(scope, receive, send)
  File "/Users/quick/Desktop/bill_generator-main/backend/venv/lib/python3.13/site-packages/starlette/_exception_handler.py", line 64, in wrapped_app
    raise exc
  File "/Users/quick/Desktop/bill_generator-main/backend/venv/lib/python3.13/site-packages/starlette/_exception_handler.py", line 53, in wrapped_app
    await app(scope, receive, sender)
  File "/Users/quick/Desktop/bill_generator-main/backend/venv/lib/python3.13/site-packages/starlette/routing.py", line 72, in app
    response = await func(request)
               ^^^^^^^^^^^^^^^^^^^
  File "/Users/quick/Desktop/bill_generator-main/backend/venv/lib/python3.13/site-packages/fastapi/routing.py", line 296, in app
    content = await serialize_response(
              ^^^^^^^^^^^^^^^^^^^^^^^^^
    ...<9 lines>...
    )
    ^
  File "/Users/quick/Desktop/bill_generator-main/backend/venv/lib/python3.13/site-packages/fastapi/routing.py", line 180, in serialize_response
    return jsonable_encoder(response_content)
  File "/Users/quick/Desktop/bill_generator-main/backend/venv/lib/python3.13/site-packages/fastapi/encoders.py", line 287, in jsonable_encoder
    encoded_value = jsonable_encoder(
        value,
    ...<4 lines>...
        sqlalchemy_safe=sqlalchemy_safe,
    )
  File "/Users/quick/Desktop/bill_generator-main/backend/venv/lib/python3.13/site-packages/fastapi/encoders.py", line 287, in jsonable_encoder
    encoded_value = jsonable_encoder(
        value,
    ...<4 lines>...
        sqlalchemy_safe=sqlalchemy_safe,
    )
  File "/Users/quick/Desktop/bill_generator-main/backend/venv/lib/python3.13/site-packages/fastapi/encoders.py", line 330, in jsonable_encoder
    raise ValueError(errors) from e
ValueError: [TypeError("'ObjectId' object is not iterable"), TypeError('vars() argument must have __dict__ attribute')]
INFO:     127.0.0.1:63845 - "POST /api/business/profile HTTP/1.1" 200 OK
INFO:     127.0.0.1:63845 - "POST /api/business/generate-template HTTP/1.1" 500 Internal Server Error
ERROR:    Exception in ASGI application
Traceback (most recent call last):
  File "/Users/quick/Desktop/bill_generator-main/backend/venv/lib/python3.13/site-packages/fastapi/encoders.py", line 322, in jsonable_encoder
    data = dict(obj)
TypeError: 'ObjectId' object is not iterable

During handling of the above exception, another exception occurred:

Traceback (most recent call last):
  File "/Users/quick/Desktop/bill_generator-main/backend/venv/lib/python3.13/site-packages/fastapi/encoders.py", line 327, in jsonable_encoder
    data = vars(obj)
TypeError: vars() argument must have __dict__ attribute

The above exception was the direct cause of the following exception:

Traceback (most recent call last):
  File "/Users/quick/Desktop/bill_generator-main/backend/venv/lib/python3.13/site-packages/uvicorn/protocols/http/h11_impl.py", line 408, in run_asgi
    result = await app(  # type: ignore[func-returns-value]
             ^^^^^^^^^^^^^^^^^^^^^^^^^^^^^^^^^^^^^^^^^^^^^^
        self.scope, self.receive, self.send
        ^^^^^^^^^^^^^^^^^^^^^^^^^^^^^^^^^^^
    )
    ^
  File "/Users/quick/Desktop/bill_generator-main/backend/venv/lib/python3.13/site-packages/uvicorn/middleware/proxy_headers.py", line 84, in __call__
    return await self.app(scope, receive, send)
           ^^^^^^^^^^^^^^^^^^^^^^^^^^^^^^^^^^^^
  File "/Users/quick/Desktop/bill_generator-main/backend/venv/lib/python3.13/site-packages/fastapi/applications.py", line 1054, in __call__
    await super().__call__(scope, receive, send)
  File "/Users/quick/Desktop/bill_generator-main/backend/venv/lib/python3.13/site-packages/starlette/applications.py", line 123, in __call__
    await self.middleware_stack(scope, receive, send)
  File "/Users/quick/Desktop/bill_generator-main/backend/venv/lib/python3.13/site-packages/starlette/middleware/errors.py", line 186, in __call__
    raise exc
  File "/Users/quick/Desktop/bill_generator-main/backend/venv/lib/python3.13/site-packages/starlette/middleware/errors.py", line 164, in __call__
    await self.app(scope, receive, _send)
  File "/Users/quick/Desktop/bill_generator-main/backend/venv/lib/python3.13/site-packages/starlette/middleware/cors.py", line 93, in __call__
    await self.simple_response(scope, receive, send, request_headers=headers)
  File "/Users/quick/Desktop/bill_generator-main/backend/venv/lib/python3.13/site-packages/starlette/middleware/cors.py", line 148, in simple_response
    await self.app(scope, receive, send)
  File "/Users/quick/Desktop/bill_generator-main/backend/venv/lib/python3.13/site-packages/starlette/middleware/exceptions.py", line 65, in __call__
    await wrap_app_handling_exceptions(self.app, conn)(scope, receive, send)
  File "/Users/quick/Desktop/bill_generator-main/backend/venv/lib/python3.13/site-packages/starlette/_exception_handler.py", line 64, in wrapped_app
    raise exc
  File "/Users/quick/Desktop/bill_generator-main/backend/venv/lib/python3.13/site-packages/starlette/_exception_handler.py", line 53, in wrapped_app
    await app(scope, receive, sender)
  File "/Users/quick/Desktop/bill_generator-main/backend/venv/lib/python3.13/site-packages/starlette/routing.py", line 756, in __call__
    await self.middleware_stack(scope, receive, send)
  File "/Users/quick/Desktop/bill_generator-main/backend/venv/lib/python3.13/site-packages/starlette/routing.py", line 776, in app
    await route.handle(scope, receive, send)
  File "/Users/quick/Desktop/bill_generator-main/backend/venv/lib/python3.13/site-packages/starlette/routing.py", line 297, in handle
    await self.app(scope, receive, send)
  File "/Users/quick/Desktop/bill_generator-main/backend/venv/lib/python3.13/site-packages/starlette/routing.py", line 77, in app
    await wrap_app_handling_exceptions(app, request)(scope, receive, send)
  File "/Users/quick/Desktop/bill_generator-main/backend/venv/lib/python3.13/site-packages/starlette/_exception_handler.py", line 64, in wrapped_app
    raise exc
  File "/Users/quick/Desktop/bill_generator-main/backend/venv/lib/python3.13/site-packages/starlette/_exception_handler.py", line 53, in wrapped_app
    await app(scope, receive, sender)
  File "/Users/quick/Desktop/bill_generator-main/backend/venv/lib/python3.13/site-packages/starlette/routing.py", line 72, in app
    response = await func(request)
               ^^^^^^^^^^^^^^^^^^^
  File "/Users/quick/Desktop/bill_generator-main/backend/venv/lib/python3.13/site-packages/fastapi/routing.py", line 296, in app
    content = await serialize_response(
              ^^^^^^^^^^^^^^^^^^^^^^^^^
    ...<9 lines>...
    )
    ^
  File "/Users/quick/Desktop/bill_generator-main/backend/venv/lib/python3.13/site-packages/fastapi/routing.py", line 180, in serialize_response
    return jsonable_encoder(response_content)
  File "/Users/quick/Desktop/bill_generator-main/backend/venv/lib/python3.13/site-packages/fastapi/encoders.py", line 287, in jsonable_encoder
    encoded_value = jsonable_encoder(
        value,
    ...<4 lines>...
        sqlalchemy_safe=sqlalchemy_safe,
    )
  File "/Users/quick/Desktop/bill_generator-main/backend/venv/lib/python3.13/site-packages/fastapi/encoders.py", line 287, in jsonable_encoder
    encoded_value = jsonable_encoder(
        value,
    ...<4 lines>...
        sqlalchemy_safe=sqlalchemy_safe,
    )
  File "/Users/quick/Desktop/bill_generator-main/backend/venv/lib/python3.13/site-packages/fastapi/encoders.py", line 330, in jsonable_encoder
    raise ValueError(errors) from e
ValueError: [TypeError("'ObjectId' object is not iterable"), TypeError('vars() argument must have __dict__ attribute')]
INFO:     127.0.0.1:63854 - "POST /api/business/profile HTTP/1.1" 200 OK
INFO:     127.0.0.1:63854 - "POST /api/business/generate-template HTTP/1.1" 500 Internal Server Error
ERROR:    Exception in ASGI application
Traceback (most recent call last):
  File "/Users/quick/Desktop/bill_generator-main/backend/venv/lib/python3.13/site-packages/fastapi/encoders.py", line 322, in jsonable_encoder
    data = dict(obj)
TypeError: 'ObjectId' object is not iterable

During handling of the above exception, another exception occurred:

Traceback (most recent call last):
  File "/Users/quick/Desktop/bill_generator-main/backend/venv/lib/python3.13/site-packages/fastapi/encoders.py", line 327, in jsonable_encoder
    data = vars(obj)
TypeError: vars() argument must have __dict__ attribute

The above exception was the direct cause of the following exception:

Traceback (most recent call last):
  File "/Users/quick/Desktop/bill_generator-main/backend/venv/lib/python3.13/site-packages/uvicorn/protocols/http/h11_impl.py", line 408, in run_asgi
    result = await app(  # type: ignore[func-returns-value]
             ^^^^^^^^^^^^^^^^^^^^^^^^^^^^^^^^^^^^^^^^^^^^^^
        self.scope, self.receive, self.send
        ^^^^^^^^^^^^^^^^^^^^^^^^^^^^^^^^^^^
    )
    ^
  File "/Users/quick/Desktop/bill_generator-main/backend/venv/lib/python3.13/site-packages/uvicorn/middleware/proxy_headers.py", line 84, in __call__
    return await self.app(scope, receive, send)
           ^^^^^^^^^^^^^^^^^^^^^^^^^^^^^^^^^^^^
  File "/Users/quick/Desktop/bill_generator-main/backend/venv/lib/python3.13/site-packages/fastapi/applications.py", line 1054, in __call__
    await super().__call__(scope, receive, send)
  File "/Users/quick/Desktop/bill_generator-main/backend/venv/lib/python3.13/site-packages/starlette/applications.py", line 123, in __call__
    await self.middleware_stack(scope, receive, send)
  File "/Users/quick/Desktop/bill_generator-main/backend/venv/lib/python3.13/site-packages/starlette/middleware/errors.py", line 186, in __call__
    raise exc
  File "/Users/quick/Desktop/bill_generator-main/backend/venv/lib/python3.13/site-packages/starlette/middleware/errors.py", line 164, in __call__
    await self.app(scope, receive, _send)
  File "/Users/quick/Desktop/bill_generator-main/backend/venv/lib/python3.13/site-packages/starlette/middleware/cors.py", line 93, in __call__
    await self.simple_response(scope, receive, send, request_headers=headers)
  File "/Users/quick/Desktop/bill_generator-main/backend/venv/lib/python3.13/site-packages/starlette/middleware/cors.py", line 148, in simple_response
    await self.app(scope, receive, send)
  File "/Users/quick/Desktop/bill_generator-main/backend/venv/lib/python3.13/site-packages/starlette/middleware/exceptions.py", line 65, in __call__
    await wrap_app_handling_exceptions(self.app, conn)(scope, receive, send)
  File "/Users/quick/Desktop/bill_generator-main/backend/venv/lib/python3.13/site-packages/starlette/_exception_handler.py", line 64, in wrapped_app
    raise exc
  File "/Users/quick/Desktop/bill_generator-main/backend/venv/lib/python3.13/site-packages/starlette/_exception_handler.py", line 53, in wrapped_app
    await app(scope, receive, sender)
  File "/Users/quick/Desktop/bill_generator-main/backend/venv/lib/python3.13/site-packages/starlette/routing.py", line 756, in __call__
    await self.middleware_stack(scope, receive, send)
  File "/Users/quick/Desktop/bill_generator-main/backend/venv/lib/python3.13/site-packages/starlette/routing.py", line 776, in app
    await route.handle(scope, receive, send)
  File "/Users/quick/Desktop/bill_generator-main/backend/venv/lib/python3.13/site-packages/starlette/routing.py", line 297, in handle
    await self.app(scope, receive, send)
  File "/Users/quick/Desktop/bill_generator-main/backend/venv/lib/python3.13/site-packages/starlette/routing.py", line 77, in app
    await wrap_app_handling_exceptions(app, request)(scope, receive, send)
  File "/Users/quick/Desktop/bill_generator-main/backend/venv/lib/python3.13/site-packages/starlette/_exception_handler.py", line 64, in wrapped_app
    raise exc
  File "/Users/quick/Desktop/bill_generator-main/backend/venv/lib/python3.13/site-packages/starlette/_exception_handler.py", line 53, in wrapped_app
    await app(scope, receive, sender)
  File "/Users/quick/Desktop/bill_generator-main/backend/venv/lib/python3.13/site-packages/starlette/routing.py", line 72, in app
    response = await func(request)
               ^^^^^^^^^^^^^^^^^^^
  File "/Users/quick/Desktop/bill_generator-main/backend/venv/lib/python3.13/site-packages/fastapi/routing.py", line 296, in app
    content = await serialize_response(
              ^^^^^^^^^^^^^^^^^^^^^^^^^
    ...<9 lines>...
    )
    ^
  File "/Users/quick/Desktop/bill_generator-main/backend/venv/lib/python3.13/site-packages/fastapi/routing.py", line 180, in serialize_response
    return jsonable_encoder(response_content)
  File "/Users/quick/Desktop/bill_generator-main/backend/venv/lib/python3.13/site-packages/fastapi/encoders.py", line 287, in jsonable_encoder
    encoded_value = jsonable_encoder(
        value,
    ...<4 lines>...
        sqlalchemy_safe=sqlalchemy_safe,
    )
  File "/Users/quick/Desktop/bill_generator-main/backend/venv/lib/python3.13/site-packages/fastapi/encoders.py", line 287, in jsonable_encoder
    encoded_value = jsonable_encoder(
        value,
    ...<4 lines>...
        sqlalchemy_safe=sqlalchemy_safe,
    )
  File "/Users/quick/Desktop/bill_generator-main/backend/venv/lib/python3.13/site-packages/fastapi/encoders.py", line 330, in jsonable_encoder
    raise ValueError(errors) from e
ValueError: [TypeError("'ObjectId' object is not iterable"), TypeError('vars() argument must have __dict__ attribute')]
INFO:     127.0.0.1:63874 - "GET /api/ HTTP/1.1" 200 OK
INFO:     127.0.0.1:63880 - "OPTIONS /api/business/generate-template HTTP/1.1" 200 OK
INFO:     127.0.0.1:63894 - "POST /api/auth/register HTTP/1.1" 200 OK
INFO:     127.0.0.1:63900 - "POST /api/business/profile HTTP/1.1" 500 Internal Server Error
ERROR:    Exception in ASGI application
Traceback (most recent call last):
  File "/Users/quick/Desktop/bill_generator-main/backend/venv/lib/python3.13/site-packages/fastapi/encoders.py", line 322, in jsonable_encoder
    data = dict(obj)
TypeError: 'ObjectId' object is not iterable

During handling of the above exception, another exception occurred:

Traceback (most recent call last):
  File "/Users/quick/Desktop/bill_generator-main/backend/venv/lib/python3.13/site-packages/fastapi/encoders.py", line 327, in jsonable_encoder
    data = vars(obj)
TypeError: vars() argument must have __dict__ attribute

The above exception was the direct cause of the following exception:

Traceback (most recent call last):
  File "/Users/quick/Desktop/bill_generator-main/backend/venv/lib/python3.13/site-packages/uvicorn/protocols/http/h11_impl.py", line 408, in run_asgi
    result = await app(  # type: ignore[func-returns-value]
             ^^^^^^^^^^^^^^^^^^^^^^^^^^^^^^^^^^^^^^^^^^^^^^
        self.scope, self.receive, self.send
        ^^^^^^^^^^^^^^^^^^^^^^^^^^^^^^^^^^^
    )
    ^
  File "/Users/quick/Desktop/bill_generator-main/backend/venv/lib/python3.13/site-packages/uvicorn/middleware/proxy_headers.py", line 84, in __call__
    return await self.app(scope, receive, send)
           ^^^^^^^^^^^^^^^^^^^^^^^^^^^^^^^^^^^^
  File "/Users/quick/Desktop/bill_generator-main/backend/venv/lib/python3.13/site-packages/fastapi/applications.py", line 1054, in __call__
    await super().__call__(scope, receive, send)
  File "/Users/quick/Desktop/bill_generator-main/backend/venv/lib/python3.13/site-packages/starlette/applications.py", line 123, in __call__
    await self.middleware_stack(scope, receive, send)
  File "/Users/quick/Desktop/bill_generator-main/backend/venv/lib/python3.13/site-packages/starlette/middleware/errors.py", line 186, in __call__
    raise exc
  File "/Users/quick/Desktop/bill_generator-main/backend/venv/lib/python3.13/site-packages/starlette/middleware/errors.py", line 164, in __call__
    await self.app(scope, receive, _send)
  File "/Users/quick/Desktop/bill_generator-main/backend/venv/lib/python3.13/site-packages/starlette/middleware/cors.py", line 85, in __call__
    await self.app(scope, receive, send)
  File "/Users/quick/Desktop/bill_generator-main/backend/venv/lib/python3.13/site-packages/starlette/middleware/exceptions.py", line 65, in __call__
    await wrap_app_handling_exceptions(self.app, conn)(scope, receive, send)
  File "/Users/quick/Desktop/bill_generator-main/backend/venv/lib/python3.13/site-packages/starlette/_exception_handler.py", line 64, in wrapped_app
    raise exc
  File "/Users/quick/Desktop/bill_generator-main/backend/venv/lib/python3.13/site-packages/starlette/_exception_handler.py", line 53, in wrapped_app
    await app(scope, receive, sender)
  File "/Users/quick/Desktop/bill_generator-main/backend/venv/lib/python3.13/site-packages/starlette/routing.py", line 756, in __call__
    await self.middleware_stack(scope, receive, send)
  File "/Users/quick/Desktop/bill_generator-main/backend/venv/lib/python3.13/site-packages/starlette/routing.py", line 776, in app
    await route.handle(scope, receive, send)
  File "/Users/quick/Desktop/bill_generator-main/backend/venv/lib/python3.13/site-packages/starlette/routing.py", line 297, in handle
    await self.app(scope, receive, send)
  File "/Users/quick/Desktop/bill_generator-main/backend/venv/lib/python3.13/site-packages/starlette/routing.py", line 77, in app
    await wrap_app_handling_exceptions(app, request)(scope, receive, send)
  File "/Users/quick/Desktop/bill_generator-main/backend/venv/lib/python3.13/site-packages/starlette/_exception_handler.py", line 64, in wrapped_app
    raise exc
  File "/Users/quick/Desktop/bill_generator-main/backend/venv/lib/python3.13/site-packages/starlette/_exception_handler.py", line 53, in wrapped_app
    await app(scope, receive, sender)
  File "/Users/quick/Desktop/bill_generator-main/backend/venv/lib/python3.13/site-packages/starlette/routing.py", line 72, in app
    response = await func(request)
               ^^^^^^^^^^^^^^^^^^^
  File "/Users/quick/Desktop/bill_generator-main/backend/venv/lib/python3.13/site-packages/fastapi/routing.py", line 296, in app
    content = await serialize_response(
              ^^^^^^^^^^^^^^^^^^^^^^^^^
    ...<9 lines>...
    )
    ^
  File "/Users/quick/Desktop/bill_generator-main/backend/venv/lib/python3.13/site-packages/fastapi/routing.py", line 180, in serialize_response
    return jsonable_encoder(response_content)
  File "/Users/quick/Desktop/bill_generator-main/backend/venv/lib/python3.13/site-packages/fastapi/encoders.py", line 287, in jsonable_encoder
    encoded_value = jsonable_encoder(
        value,
    ...<4 lines>...
        sqlalchemy_safe=sqlalchemy_safe,
    )
  File "/Users/quick/Desktop/bill_generator-main/backend/venv/lib/python3.13/site-packages/fastapi/encoders.py", line 287, in jsonable_encoder
    encoded_value = jsonable_encoder(
        value,
    ...<4 lines>...
        sqlalchemy_safe=sqlalchemy_safe,
    )
  File "/Users/quick/Desktop/bill_generator-main/backend/venv/lib/python3.13/site-packages/fastapi/encoders.py", line 330, in jsonable_encoder
    raise ValueError(errors) from e
ValueError: [TypeError("'ObjectId' object is not iterable"), TypeError('vars() argument must have __dict__ attribute')]
WARNING:  StatReload detected changes in 'server.py'. Reloading...
INFO:     Shutting down
INFO:     Waiting for application shutdown.
2025-08-14 08:40:02,303 - server - INFO - ðŸ”’ InvoiceForge API shut down successfully!
INFO:     Application shutdown complete.
INFO:     Finished server process [82091]
Fatal Python error: init_sys_streams: can't initialize sys standard streams
Python runtime state: core initialized
OSError: [Errno 9] Bad file descriptor

Current thread 0x000000020cb120c0 (most recent call first):
  <no Python frame>
WARNING:  StatReload detected changes in 'server.py'. Reloading...
Fatal Python error: init_sys_streams: can't initialize sys standard streams
Python runtime state: core initialized
OSError: [Errno 9] Bad file descriptor

Current thread 0x000000020cb120c0 (most recent call first):
  <no Python frame>
INFO:     Stopping reloader process [82034]
